Workbook
Name ETkoProjCurr: 0
Name ETkoProjName: 0
Name TABLE: 'Private Paving'!$Q$56:$U$56
Name TABLE: 'ROW Paving'!$Q$56:$U$56
Name TABLE_2: 'Private Paving'!$Q$56:$U$56
Name TABLE_2: 'ROW Paving'!$Q$56:$U$56
Name TABLE_3: 'Private Paving'!$Q$56:$U$56
Name TABLE_3: 'ROW Paving'!$Q$56:$U$56

Sheet Summary
B2: JOB NAME: | C2: =Information!C2 -> 0 | O2: DATE | P2: REV
B3: JOB ADDRESS: | C3: =Information!C3 -> 0 | J3: ARCHITECTUAL: | K3: =Information!I13 -> 0 | O3: =Information!L13 -> 0
B4: CITY, STATE: | C4: =Information!C4 -> 0 | J4: STRUCTURAL: | K4: =Information!I14 -> 0 | O4: =Information!L14 -> 0 | S4: Entered by: | T4: =Information!C8 -> Chad McKinney
C5: NUMBER | E5: DATE | J5: CIVIL: | K5: =Information!I15 -> 0 | O5: =Information!L15 -> 0 | S5: =Information!H5 -> Approved by Chad:
B6: BID: | C6: =Information!I2 -> 0 | E6: =Information!J2 -> 0 | J6: LANDSCAPE: | K6: =Information!I16 -> 0 | O6: =Information!L16 -> 0 | S6: =Information!H6 -> Approved by Edward:
B7: REVISION: | C7: =Information!I3 -> 0 | E7: =Information!J3 -> 0 | M7: JOB COST SUMMARY
B8: Concrete Supplier: | D8: =Pricing!A2 -> Martin Marrieta | G8: FORMS | H8: Sand & Rock | I8: P.T. CABLES | J8: REBAR | K8: REBAR ACCES. | L8: CON CRETE | M8: SEALERS CURE | N8: OTHER SUBS | O8: SUB LABOR | P8: LABOR | Q8: SUPV | R8: EQUIP | S8: OUT OF TOWN | T8: COST BY UNIT | U8: TOTAL COST | V8: %
E9: SALE | F9: Sale by | V9: of
A10: DESCRIPTION | C10: QUANTITY | D10: UNT | E10: AMOUNT | F10: Unit | V10: sale | W10: CY
A12: MONO SLABS Garden Style | C12: ='Mono Slab on Grade Garden Style'!I83 -> 0 | D12: SF | E12: ='Mono Slab on Grade Garden Style'!E64 -> 0 | F12: =IF(C12=0,0,E12/$C$12) -> 0 | G12: ='Mono Slab on Grade Garden Style'!AO83+'Mono Slab on Grade Garden Style'!AO96+'Mono Slab on Grade Garden Style'!AO90++'Mono Slab on Grade Garden Style'!AO135 -> 0 | H12: ='Mono Slab on Grade Garden Style'!AO84+'Mono Slab on Grade Garden Style'!AO85 -> 0 | I12: ='Mono Slab on Grade Garden Style'!AO88 -> 0 | J12: ='Mono Slab on Grade Garden Style'!AO86 -> 0 | K12: ='Mono Slab on Grade Garden Style'!AO87 -> 0 | L12: ='Mono Slab on Grade Garden Style'!AO89 -> 0 | M12: ='Mono Slab on Grade Garden Style'!AO91 -> 0 | N12: ='Mono Slab on Grade Garden Style'!AO106+'Mono Slab on Grade Garden Style'!AO107+'Mono Slab on Grade Garden Style'!AO108+'Mono Slab on Grade Garden Style'!AO109+'Mono Slab on Grade Garden Style'!AO110+'Mono Slab on Grade Garden Style'!AO111 -> 0 | O12: ='Mono Slab on Grade Garden Style'!AO113+'Mono Slab on Grade Garden Style'!AO114+'Mono Slab on Grade Garden Style'!AO115+'Mono Slab on Grade Garden Style'!AO116+'Mono Slab on Grade Garden Style'!AO117+'Mono Slab on Grade Garden Style'!AO118+'Mono Slab on Grade Garden Style'!AO119+'Mono Slab on Grade Garden Style'!AO120+'Mono Slab on Grade Garden Style'!AO121+'Mono Slab on Grade Garden Style'!AO122+'Mono Slab on Grade Garden Style'!AO125+'Mono Slab on Grade Garden Style'!AO126+'Mono Slab on Grade Garden Style'!AO127+'Mono Slab on Grade Garden Style'!AO128+'Mono Slab on Grade Garden Style'!AO129+'Mono Slab on Grade Garden Style'!AO130+'Mono Slab on Grade Garden Style'!AO131+'Mono Slab on Grade Garden Style'!AO132 -> 0 | P12: ='Mono Slab on Grade Garden Style'!AO102 -> 0 | Q12: ='Mono Slab on Grade Garden Style'!AO100+'Mono Slab on Grade Garden Style'!AO101 -> 0 | R12: ='Mono Slab on Grade Garden Style'!AO133+'Mono Slab on Grade Garden Style'!AO134 -> 0 | S12: ='Mono Slab on Grade Garden Style'!AO103 -> 0 | U12: =IF(C12=0,0,SUM(G12:T12)) -> 0 | V12: =IF(C12=0,0,1-(U12/E12)) -> 0 | W12: =SUM('Mono Slab on Grade Garden Style'!L71:L73) -> 0 | X12: ='Mono Slab on Grade Garden Style'!AC64 -> 0 | Y12: =X12-U12 -> 0
G13: =IF(C12=0,0,G12/C12) -> 0 | H13: =IF($C12=0,0,H12/$C$12) -> 0 | I13: =IF($C12=0,0,I12/$C$12) -> 0 | J13: =IF($C12=0,0,J12/$C$12) -> 0 | K13: =IF($C12=0,0,K12/$C$12) -> 0 | L13: =IF($C12=0,0,L12/$C$12) -> 0 | M13: =IF($C12=0,0,M12/$C$12) -> 0 | N13: =IF($C12=0,0,N12/$C$12) -> 0 | O13: =IF($C12=0,0,O12/$C$12) -> 0 | ... S13: =IF($C12=0,0,S12/$C$12) -> 0 | T13: =SUM(G13:S13) -> 0 | X13: .
A14: MONO SLABS Wrap Bld 1 | C14: ='Mono Slab on Grade Building 1'!I83 -> 0 | D14: SF | E14: ='Mono Slab on Grade Building 1'!E64 -> 0 | F14: =IF(C14=0,0,E14/$C$14) -> 0 | G14: ='Mono Slab on Grade Building 1'!AO83+'Mono Slab on Grade Building 1'!AO96+'Mono Slab on Grade Building 1'!AO90++'Mono Slab on Grade Building 1'!AO135 -> 0 | H14: ='Mono Slab on Grade Building 1'!AO84+'Mono Slab on Grade Building 1'!AO85 -> 0 | I14: ='Mono Slab on Grade Building 1'!AO88 -> 0 | J14: ='Mono Slab on Grade Building 1'!AO86 -> 0 | K14: ='Mono Slab on Grade Building 1'!AO87 -> 0 | L14: ='Mono Slab on Grade Building 1'!AO89 -> 0 | M14: ='Mono Slab on Grade Building 1'!AO91 -> 0 | N14: ='Mono Slab on Grade Building 1'!AO106+'Mono Slab on Grade Building 1'!AO107+'Mono Slab on Grade Building 1'!AO108+'Mono Slab on Grade Building 1'!AO109+'Mono Slab on Grade Building 1'!AO110+'Mono Slab on Grade Building 1'!AO111 -> 0 | O14: ='Mono Slab on Grade Building 1'!AO113+'Mono Slab on Grade Building 1'!AO114+'Mono Slab on Grade Building 1'!AO115+'Mono Slab on Grade Building 1'!AO116+'Mono Slab on Grade Building 1'!AO117+'Mono Slab on Grade Building 1'!AO118+'Mono Slab on Grade Building 1'!AO119+'Mono Slab on Grade Building 1'!AO120+'Mono Slab on Grade Building 1'!AO121+'Mono Slab on Grade Building 1'!AO122+'Mono Slab on Grade Building 1'!AO125+'Mono Slab on Grade Building 1'!AO126+'Mono Slab on Grade Building 1'!AO127+'Mono Slab on Grade Building 1'!AO128+'Mono Slab on Grade Building 1'!AO129+'Mono Slab on Grade Building 1'!AO130+'Mono Slab on Grade Building 1'!AO131+'Mono Slab on Grade Building 1'!AO132 -> 0 | P14: ='Mono Slab on Grade Building 1'!AO102 -> 0 | Q14: ='Mono Slab on Grade Building 1'!AO100+'Mono Slab on Grade Building 1'!AO101 -> 0 | R14: ='Mono Slab on Grade Building 1'!AO133+'Mono Slab on Grade Building 1'!AO134 -> 0 | S14: ='Mono Slab on Grade Building 1'!AO103 -> 0 | U14: =IF(C14=0,0,SUM(G14:T14)) -> 0 | V14: =IF(C14=0,0,1-(U14/E14)) -> 0 | W14: =SUM('Mono Slab on Grade Building 1'!L71:L73) -> 0 | X14: ='Mono Slab on Grade Building 1'!AC64 -> 0 | Y14: =X14-U14 -> 0
C15: ='Mono Slab on Grade Building 1'!I84 -> 0 | G15: =IF(C14=0,0,G14/C14) -> 0 | H15: =IF($C14=0,0,H14/$C$14) -> 0 | I15: =IF($C14=0,0,I14/$C$14) -> 0 | J15: =IF($C14=0,0,J14/$C$14) -> 0 | K15: =IF($C14=0,0,K14/$C$14) -> 0 | L15: =IF($C14=0,0,L14/$C$14) -> 0 | M15: =IF($C14=0,0,M14/$C$14) -> 0 | N15: =IF($C14=0,0,N14/$C$14) -> 0 | O15: =IF($C14=0,0,O14/$C$14) -> 0 | ... S15: =IF($C14=0,0,S14/$C$14) -> 0 | T15: =SUM(G15:S15) -> 0 | X15: .
A16: MONO SLABS Wrap Bld 2 | C16: ='Mono Slab on Grade Building 2'!I83 -> 0 | D16: SF | E16: ='Mono Slab on Grade Building 2'!E64 -> 0 | F16: =IF(C16=0,0,E16/$C$12) -> 0 | G16: ='Mono Slab on Grade Building 2'!AO83+'Mono Slab on Grade Building 2'!AO96+'Mono Slab on Grade Building 2'!AO90++'Mono Slab on Grade Building 2'!AO135 -> 0 | H16: ='Mono Slab on Grade Building 2'!AO84+'Mono Slab on Grade Building 2'!AO85 -> 0 | I16: ='Mono Slab on Grade Building 2'!AO88 -> 0 | J16: ='Mono Slab on Grade Building 2'!AO86 -> 0 | K16: ='Mono Slab on Grade Building 2'!AO87 -> 0 | L16: ='Mono Slab on Grade Building 2'!AO89 -> 0 | M16: ='Mono Slab on Grade Building 2'!AO91 -> 0 | N16: ='Mono Slab on Grade Building 2'!AO106+'Mono Slab on Grade Building 2'!AO107+'Mono Slab on Grade Building 2'!AO108+'Mono Slab on Grade Building 2'!AO109+'Mono Slab on Grade Building 2'!AO110+'Mono Slab on Grade Building 2'!AO111 -> 0 | O16: ='Mono Slab on Grade Building 2'!AO113+'Mono Slab on Grade Building 2'!AO114+'Mono Slab on Grade Building 2'!AO115+'Mono Slab on Grade Building 2'!AO116+'Mono Slab on Grade Building 2'!AO117+'Mono Slab on Grade Building 2'!AO118+'Mono Slab on Grade Building 2'!AO119+'Mono Slab on Grade Building 2'!AO120+'Mono Slab on Grade Building 2'!AO121+'Mono Slab on Grade Building 2'!AO122+'Mono Slab on Grade Building 2'!AO125+'Mono Slab on Grade Building 2'!AO126+'Mono Slab on Grade Building 2'!AO127+'Mono Slab on Grade Building 2'!AO128+'Mono Slab on Grade Building 2'!AO129+'Mono Slab on Grade Building 2'!AO130+'Mono Slab on Grade Building 2'!AO131+'Mono Slab on Grade Building 2'!AO132 -> 0 | P16: ='Mono Slab on Grade Building 2'!AO102 -> 0 | Q16: ='Mono Slab on Grade Building 2'!AO100+'Mono Slab on Grade Building 2'!AO101 -> 0 | R16: ='Mono Slab on Grade Building 2'!AO133+'Mono Slab on Grade Building 2'!AO134 -> 0 | S16: ='Mono Slab on Grade Building 2'!AO103 -> 0 | U16: =IF(C16=0,0,SUM(G16:T16)) -> 0 | V16: =IF(C16=0,0,1-(U16/E16)) -> 0 | W16: =SUM('Mono Slab on Grade Building 2'!L71:L73) -> 0 | X16: ='Mono Slab on Grade Building 2'!AC64 -> 0 | Y16: =X16-U16 -> 0
G17: =IF(C16=0,0,G16/C16) -> 0 | H17: =IF($C16=0,0,H16/$C$12) -> 0 | I17: =IF($C16=0,0,I16/$C$12) -> 0 | J17: =IF($C16=0,0,J16/$C$12) -> 0 | K17: =IF($C16=0,0,K16/$C$12) -> 0 | L17: =IF($C16=0,0,L16/$C$12) -> 0 | M17: =IF($C16=0,0,M16/$C$12) -> 0 | N17: =IF($C16=0,0,N16/$C$12) -> 0 | O17: =IF($C16=0,0,O16/$C$12) -> 0 | ... S17: =IF($C16=0,0,S16/$C$12) -> 0 | T17: =SUM(G17:S17) -> 0 | X17: .
A19: PIERS | C19: =PIERS!E39 -> 0 | D19: EA | E19: =PIERS!E42 -> 0 | F19: =IF(C19=0,0,E19/C19) -> 0 | G19: =SUM(PIERS!W49:W70) -> 0 | J19: =PIERS!O52 -> 0 | K19: =SUM(PIERS!W71:W76) -> 0 | L19: =SUM(PIERS!O49:P51) -> 0 | M19: =SUM(PIERS!W77:W79) -> 0 | N19: =SUM(PIERS!O76:P81)-PIERS!O80+PIERS!O53 -> 0 | O19: =SUM(PIERS!O56:P60) -> 0 | P19: =SUM(PIERS!L56:M60) -> 0 | Q19: =SUM(PIERS!O63:P67) -> 0 | R19: =PIERS!AE125+PIERS!AE126 -> 0 | S19: =PIERS!O80 -> 0 | U19: =IF(C19=0,0,SUM(G19:T19)) -> 0 | V19: =IF(C19=0,0,1-(U19/E19)) -> 0 | W19: =PIERS!S39 -> 0 | X19: =PIERS!T42 -> 0 | Y19: =X19-U19 -> 0
A20: GRADE BEAMS | C20: ='Gd Beams'!I63 -> 0 | D20: SF | E20: ='Gd Beams'!E41 -> 0 | F20: =IF(C20=0,0,E20/C20) -> 0 | G20: ='Gd Beams'!AF67+'Gd Beams'!AF74+'Gd Beams'!AF117 -> 0 | H20: ='Gd Beams'!AF68+'Gd Beams'!AF69 -> 0 | I20: ='Gd Beams'!AF72 -> 0 | J20: ='Gd Beams'!AF70 -> 0 | K20: ='Gd Beams'!AF71 -> 0 | L20: ='Gd Beams'!AF73 -> 0 | M20: ='Gd Beams'!AF75 -> 0 | N20: ='Gd Beams'!AF88+'Gd Beams'!AF89+'Gd Beams'!AF90+'Gd Beams'!AF91+'Gd Beams'!AF92+'Gd Beams'!AF93 -> 0 | O20: =SUM('Gd Beams'!AF95:AF114) -> 0 | P20: ='Gd Beams'!AF84 -> 0 | Q20: ='Gd Beams'!AF82+'Gd Beams'!AF83 -> 0 | R20: ='Gd Beams'!AF115+'Gd Beams'!AF116 -> 0 | S20: ='Gd Beams'!AF85 -> 0 | T20: =IF(U20=0,0,SUM(G20:S20)/C20) -> 0 | U20: =IF(C20=0,0,SUM(G20:S20)) -> 0 | V20: =IF(C20=0,0,1-(U20/E20)) -> 0 | W20: ='Gd Beams'!L49+'Gd Beams'!L50+'Gd Beams'!L51 -> 0 | X20: ='Gd Beams'!U41 -> 0 | Y20: =X20-U20 -> 0
A21: GD Beams or Cont Footings | C21: ='Gd Beams or Cont Footings'!I63 -> 0 | D21: SF | E21: ='Gd Beams or Cont Footings'!E41 -> 0 | F21: =IF(C21=0,0,E21/C21) -> 0 | G21: ='Gd Beams or Cont Footings'!AF67+'Gd Beams or Cont Footings'!AF74+'Gd Beams or Cont Footings'!AF117 -> 0 | H21: ='Gd Beams or Cont Footings'!AF68+'Gd Beams or Cont Footings'!AF69 -> 0 | I21: ='Gd Beams or Cont Footings'!AF72 -> 0 | J21: ='Gd Beams or Cont Footings'!AF70 -> 0 | K21: ='Gd Beams or Cont Footings'!AF71 -> 0 | L21: ='Gd Beams or Cont Footings'!AF73 -> 0 | M21: ='Gd Beams or Cont Footings'!AF75 -> 0 | N21: ='Gd Beams or Cont Footings'!AF88+'Gd Beams or Cont Footings'!AF89+'Gd Beams or Cont Footings'!AF90+'Gd Beams or Cont Footings'!AF91+'Gd Beams or Cont Footings'!AF92+'Gd Beams or Cont Footings'!AF93 -> 0 | O21: =SUM('Gd Beams or Cont Footings'!AF95:AF114) -> 0 | P21: ='Gd Beams or Cont Footings'!AF84 -> 0 | Q21: ='Gd Beams or Cont Footings'!AF82+'Gd Beams or Cont Footings'!AF83 -> 0 | R21: ='Gd Beams or Cont Footings'!AF115+'Gd Beams or Cont Footings'!AF116 -> 0 | S21: ='Gd Beams or Cont Footings'!AF85 -> 0 | T21: =IF(U21=0,0,SUM(G21:S21)/C21) -> 0 | U21: =IF(C21=0,0,SUM(G21:S21)) -> 0 | V21: =IF(C21=0,0,1-(U21/E21)) -> 0 | W21: ='Gd Beams or Cont Footings'!L49+'Gd Beams or Cont Footings'!L50+'Gd Beams or Cont Footings'!L51 -> 0 | X21: ='Gd Beams or Cont Footings'!U41 -> 0 | Y21: =X21-U21 -> 0
A22: SLAB ON DECK | C22: ='SLAB ON DECK'!C27:D27 -> 0 | D22: SF | E22: ='SLAB ON DECK'!D31 -> 0 | F22: =IF(C22=0,0,E22/C22) -> 0 | G22: =SUM('SLAB ON DECK'!W38:W63)+'SLAB ON DECK'!N43 -> 0 | H22: ='SLAB ON DECK'!N45+'SLAB ON DECK'!N46 -> 0 | I22: ='SLAB ON DECK'!N44 -> 0 | J22: ='SLAB ON DECK'!N41+'SLAB ON DECK'!N42 -> 0 | K22: =SUM('SLAB ON DECK'!W64:W69) -> 0 | L22: =SUM('SLAB ON DECK'!N38:O40) -> 0 | M22: =SUM('SLAB ON DECK'!W70:W72) -> 0 | N22: =SUM('SLAB ON DECK'!N67:O73)+'SLAB ON DECK'!N75 -> 0 | O22: =SUM('SLAB ON DECK'!N50:O55) -> 0 | P22: =SUM('SLAB ON DECK'!K50:L55) -> 0 | Q22: =SUM('SLAB ON DECK'!N58:O60) -> 0 | R22: ='SLAB ON DECK'!AD115+'SLAB ON DECK'!AD116 -> 0 | S22: ='SLAB ON DECK'!N74 -> 0 | T22: =IF(C22=0,0,U22/C22) -> 0 | U22: =IF(C22=0,0,SUM(G22:S22)) -> 0 | V22: =IF(C22=0,0,1-(U22/E22)) -> 0 | W22: ='SLAB ON DECK'!K38+'SLAB ON DECK'!K39+'SLAB ON DECK'!K40 -> 0 | X22: ='SLAB ON DECK'!T31 -> 0 | Y22: =X22-U22 -> 0
G23: =IF($C$22=0,0,G22/$C$22) -> 0 | H23: =IF($C$22=0,0,H22/$C$22) -> 0 | I23: =IF($C$22=0,0,I22/$C$22) -> 0 | J23: =IF($C$22=0,0,J22/$C$22) -> 0 | K23: =IF($C$22=0,0,K22/$C$22) -> 0 | L23: =IF($C$22=0,0,L22/$C$22) -> 0 | M23: =IF($C$22=0,0,M22/$C$22) -> 0 | N23: =IF($C$22=0,0,N22/$C$22) -> 0 | ... S23: =IF($C$22=0,0,S22/$C$22) -> 0 | T23: =SUM(G23:S23) -> 0 | Y23: =X23-U23 -> 0
A24: CIP ELEV. SLAB | C24: ='CIP EL. DECK'!D41 -> 0 | D24: SF | E24: ='CIP EL. DECK'!E52 -> 0 | F24: =IF(C24=0,0,E24/C24) -> 0 | G24: ='CIP EL. DECK'!AF70+'CIP EL. DECK'!AF121 -> 0 | H24: ='CIP EL. DECK'!AF71 -> 0 | I24: ='CIP EL. DECK'!AF75 -> 0 | J24: ='CIP EL. DECK'!AF73 -> 0 | K24: ='CIP EL. DECK'!AF74 -> 0 | L24: ='CIP EL. DECK'!AF76 -> 0 | M24: ='CIP EL. DECK'!AF78 -> 0 | N24: ='CIP EL. DECK'!AF92+'CIP EL. DECK'!AF96+'CIP EL. DECK'!O68+'CIP EL. DECK'!O69 -> 0 | O24: ='CIP EL. DECK'!AF101+'CIP EL. DECK'!AF102+'CIP EL. DECK'!AF103+'CIP EL. DECK'!AF104+'CIP EL. DECK'!AF105+'CIP EL. DECK'!AF118+'CIP EL. DECK'!AF110 -> 0 | P24: ='CIP EL. DECK'!AF88 -> 0 | Q24: ='CIP EL. DECK'!AF86+'CIP EL. DECK'!AF87 -> 0 | R24: ='CIP EL. DECK'!AF119+'CIP EL. DECK'!AF120 -> 0 | S24: ='CIP EL. DECK'!AF89 -> 0 | T24: =IF(C24=0,0,U24/C24) -> 0 | U24: =SUM(G24:S24) -> 0 | V24: =IF(C24=0,0,1-(U24/E24)) -> 0 | W24: ='CIP EL. DECK'!L60+'CIP EL. DECK'!L61+'CIP EL. DECK'!L62 -> 0 | X24: ='CIP EL. DECK'!U52 -> 0 | Y24: =X24-U24 -> 0
A26: SLAB ON GRADE | C26: ='SLAB ON GRADE'!H50 -> 0 | D26: SF | E26: ='SLAB ON GRADE'!D31 -> 0 | F26: =IF(C26=0,0,E26/C26) -> 0 | G26: =SUM('SLAB ON GRADE'!W38:W63)+'SLAB ON GRADE'!N43 -> 0 | H26: ='SLAB ON GRADE'!N45+'SLAB ON GRADE'!N46 -> 0 | I26: ='SLAB ON GRADE'!N44 -> 0 | J26: ='SLAB ON GRADE'!N41+'SLAB ON GRADE'!N42 -> 0 | K26: =SUM('SLAB ON GRADE'!W64:W69) -> 0 | L26: =SUM('SLAB ON GRADE'!N38:O40) -> 0 | M26: =SUM('SLAB ON GRADE'!W70:W72) -> 0 | N26: =SUM('SLAB ON GRADE'!N67:O73)+'SLAB ON GRADE'!N75 -> 0 | O26: =SUM('SLAB ON GRADE'!N50:O55) -> 0 | P26: =SUM('SLAB ON GRADE'!K50:L55) -> 0 | Q26: =SUM('SLAB ON GRADE'!N58:O60) -> 0 | R26: ='SLAB ON GRADE'!AD114+'SLAB ON GRADE'!AD115 -> 0 | S26: ='SLAB ON GRADE'!N74 -> 0 | T26: =IF(C26=0,0,U26/C26) -> 0 | U26: =IF(C26=0,0,SUM(G26:S26)) -> 0 | V26: =IF(C26=0,0,1-(U26/E26)) -> 0 | W26: ='SLAB ON GRADE'!K38+'SLAB ON GRADE'!K39+'SLAB ON GRADE'!K40 -> 0 | X26: ='SLAB ON GRADE'!T31 -> 0 | Y26: =X26-U26 -> 0
G27: =IF($C$26=0,0,G26/$C$26) -> 0 | H27: =IF($C$26=0,0,H26/$C$26) -> 0 | I27: =IF($C$26=0,0,I26/$C$26) -> 0 | J27: =IF($C$26=0,0,J26/$C$26) -> 0 | K27: =IF($C$26=0,0,K26/$C$26) -> 0 | L27: =IF($C$26=0,0,L26/$C$26) -> 0 | M27: =IF($C$26=0,0,M26/$C$26) -> 0 | N27: =IF($C$26=0,0,N26/$C$26) -> 0 | ... R27: =IF($C$26=0,0,R26/$C$26) -> 0 | S27: =IF($C$22=0,0,S26/$C$22) -> 0 | T27: =SUM(G27:S27) -> 0 | Y27: =X27-U27 -> 0
A28: COLUMNS | C28: =COLUMNS!E37 -> 0 | D28: EA | E28: =COLUMNS!E41 -> 0 | F28: =IF(C28=0,0,E28/C28) -> 0 | G28: =COLUMNS!AF67+COLUMNS!AF117 -> 0 | I28: =COLUMNS!AF72 -> 0 | J28: =COLUMNS!AF70 -> 0 | K28: =COLUMNS!AF71 -> 0 | L28: =COLUMNS!AF73 -> 0 | M28: =COLUMNS!AF75 -> 0 | N28: =COLUMNS!AF88+COLUMNS!AF79 -> 0 | O28: =COLUMNS!AF97+COLUMNS!AF98+COLUMNS!AF99+COLUMNS!AF100+COLUMNS!AF101+COLUMNS!O68+COLUMNS!O69+COLUMNS!AF110 -> 0 | P28: =COLUMNS!AF84 -> 0 | Q28: =COLUMNS!AF82+COLUMNS!AF83 -> 0 | R28: =COLUMNS!AF115+COLUMNS!AF116 -> 0 | S28: =COLUMNS!AF85 -> 0 | T28: =IF(C28=0,0,SUM(G28:S28)/C28) -> 0 | U28: =SUM(G28:S28) -> 0 | V28: =IF(C28=0,0,1-(U28/E28)) -> 0 | W28: =SUM(COLUMNS!V11:V36) -> 0 | X28: =COLUMNS!U41 -> 0 | Y28: =X28-U28 -> 0
A29: =Miscellaneous!A31 -> PANEL AND ANCHOR | C29: =Miscellaneous!F31 -> 0 | D29: EA | E29: =Miscellaneous!I31 -> 0 | F29: =IF(C29=0,0,E29/C29) -> 0 | G29: =Miscellaneous!O31 -> 0 | J29: =Miscellaneous!Q31 -> 0 | L29: =Miscellaneous!P31 -> 0 | O29: =Miscellaneous!AD31 -> 0 | Q29: =Miscellaneous!S31 -> 0 | R29: =Miscellaneous!T31 -> 0 | U29: =SUM(G29:S29) -> 0 | V29: =IF(C29=0,0,1-(U29/E29)) -> 0 | W29: =Miscellaneous!M31 -> 0 | Y29: =X29-U29 -> 0
W30: 0 | Y30: =X30-U30 -> 0
A31: =Miscellaneous!A16 -> ELEVATOR PITS | C31: =Miscellaneous!F16 -> 0 | D31: EA | E31: =Miscellaneous!I16 -> 0 | F31: =IF(C31>0,E31/C31,0) -> 0 | G31: =IF(C31>0,Miscellaneous!O16,0) -> 0 | J31: =IF(C31>0,Miscellaneous!Q16,0) -> 0 | L31: =IF(C31>0,Miscellaneous!P16,0) -> 0 | O31: =IF(C31>0,Miscellaneous!R16,0) -> 0 | Q31: =IF(C31>0,Miscellaneous!S16,0) -> 0 | R31: =IF(C31>0,Miscellaneous!T16,0) -> 0 | T31: =IF(C31=0,0,U31/C31) -> 0 | U31: =IF(C31=0,0,SUM(G31:S31)) -> 0 | V31: =IF(C31=0,0,1-(U31/E31)) -> 0 | W31: =Miscellaneous!M16 -> 0
A32: =Miscellaneous!A17 -> DOCK LEVELER PITS | C32: =Miscellaneous!F17 -> 0 | D32: EA | E32: =Miscellaneous!I17 -> 0 | F32: =IF(C32=0,0,E32/C32) -> 0 | G32: =Miscellaneous!O17 -> 0 | J32: =Miscellaneous!Q17 -> 0 | L32: =Miscellaneous!P17 -> 0 | O32: =Miscellaneous!AD17 -> 0 | Q32: =Miscellaneous!S17 -> 0 | R32: =IF(C32>0,Miscellaneous!T17,0) -> 0 | U32: =IF(C32=0,0,SUM(G32:S32)) -> 0
E33: 0
A34: TILT PANELS | C34: =PANELS!I148 -> 0 | D34: SF | E34: =PANELS!E124 -> 0 | F34: =IF(C34=0,0,E34/C34) -> 0 | G34: =PANELS!AH124+PANELS!AH131++PANELS!AH174 -> 0 | H34: =PANELS!AH125+PANELS!AH126 -> 0 | J34: =PANELS!AH127 -> 0 | K34: =PANELS!AH128 -> 0 | L34: =PANELS!AH130 -> 0 | M34: =PANELS!AH132 -> 0 | N34: =PANELS!AH145+PANELS!AH147+PANELS!AH148+PANELS!AH149+PANELS!AH150+PANELS!O168 -> 0 | O34: =PANELS!AH154+PANELS!AH155+PANELS!AH156+PANELS!AH157+PANELS!AH158+PANELS!AH159+PANELS!AH171+PANELS!AH165 -> 0 | P34: =PANELS!AH141 -> 0 | Q34: =PANELS!AH139+PANELS!AH140 -> 0 | R34: =PANELS!AH172+PANELS!AH173 -> 0 | S34: =PANELS!AH142 -> 0 | U34: =SUM(G34:S34) -> 0 | V34: =IF(C34=0,0,1-(U34/E34)) -> 0 | W34: =PANELS!L134+PANELS!L135+PANELS!L136 -> 0
A36: SITEWORK
A37: Private Paving | C37: ='Private Paving'!D28 -> 0 | D37: SF | E37: ='Private Paving'!E32 -> 0 | F37: =IF(E37=0,0,E37/C37) -> 0 | G37: =SUM('Private Paving'!W40:W65) -> 0 | H37: ='Private Paving'!O46+'Private Paving'!O47 -> 0 | J37: ='Private Paving'!O43+'Private Paving'!O44+'Private Paving'!W78 -> 0 | K37: =SUM('Private Paving'!W66:W71) -> 0 | L37: =SUM('Private Paving'!O40:P42) -> 0 | M37: =SUM('Private Paving'!W72:W75) -> 0 | N37: =SUM('Private Paving'!O70:P78)-'Private Paving'!O77 -> 0 | O37: =SUM('Private Paving'!O50:P54) -> 0 | P37: =SUM('Private Paving'!L50:M54) -> 0 | Q37: =SUM('Private Paving'!O57:P61) -> 0 | R37: ='Private Paving'!AE116+'Private Paving'!AE117 -> 0 | S37: ='Private Paving'!O77 -> 0 | U37: =IF(C37=0,0,SUM(G37:S37)) -> 0 | V37: =IF(C37=0,0,1-(U37/E37)) -> 0 | W37: =SUM('Private Paving'!L40:M42) -> 0 | X37: ='Private Paving'!U32 -> 0 | Y37: =X37-U37 -> 0
G38: =IF($C37=0,0,G37/$C37) -> 0 | H38: =IF($C37=0,0,H37/$C37) -> 0 | I38: =IF($C37=0,0,I37/$C37) -> 0 | J38: =IF($C37=0,0,J37/$C37) -> 0 | K38: =IF($C37=0,0,K37/$C37) -> 0 | L38: =IF($C37=0,0,L37/$C37) -> 0 | M38: =IF($C37=0,0,M37/$C37) -> 0 | N38: =IF($C37=0,0,N37/$C37) -> 0 | ... S38: =IF($C37=0,0,S37/$C37) -> 0 | T38: =SUM(G38:S38) -> 0 | Y38: =X38-U38 -> 0
A39: ROW Paving | C39: ='ROW Paving'!D28 -> 0 | D39: SF | E39: ='ROW Paving'!E32 -> 0 | F39: =IF(E39=0,0,E39/C39) -> 0 | G39: =SUM('ROW Paving'!W40:W65) -> 0 | H39: ='ROW Paving'!O46+'ROW Paving'!O47 -> 0 | J39: ='ROW Paving'!O43+'ROW Paving'!O44+'ROW Paving'!W78 -> 0 | K39: =SUM('ROW Paving'!W66:W71) -> 0 | L39: =SUM('ROW Paving'!O40:P42) -> 0 | M39: =SUM('ROW Paving'!W72:W75) -> 0 | N39: =SUM('ROW Paving'!O70:P78)-'ROW Paving'!O77 -> 0 | O39: =SUM('ROW Paving'!O50:P54) -> 0 | P39: =SUM('ROW Paving'!L50:M54) -> 0 | Q39: =SUM('ROW Paving'!O57:P61) -> 0 | R39: ='ROW Paving'!AE116+'ROW Paving'!AE117 -> 0 | S39: ='ROW Paving'!O77 -> 0 | U39: =IF(C39=0,0,SUM(G39:S39)) -> 0 | V39: =IF(C39=0,0,1-(U39/E39)) -> 0 | W39: =SUM('ROW Paving'!L42:M44) -> 0 | X39: ='ROW Paving'!U32 -> 0 | Y39: =X39-U39 -> 0
G40: =IF($C39=0,0,G39/$C39) -> 0 | H40: =IF($C39=0,0,H39/$C39) -> 0 | I40: =IF($C39=0,0,I39/$C39) -> 0 | J40: =IF($C39=0,0,J39/$C39) -> 0 | K40: =IF($C39=0,0,K39/$C39) -> 0 | L40: =IF($C39=0,0,L39/$C39) -> 0 | M40: =IF($C39=0,0,M39/$C39) -> 0 | N40: =IF($C39=0,0,N39/$C39) -> 0 | ... S40: =IF($C39=0,0,S39/$C39) -> 0 | T40: =SUM(G40:S40) -> 0 | Y40: =X40-U40 -> 0
Y41: =X41-U41 -> 0
A42: SIDEWALKS | C42: =SIDEWALKS!C27 -> 0 | D42: SF | E42: =SIDEWALKS!D31 -> 0 | F42: =IF(E42=0,0,E42/C42) -> 0 | G42: =SIDEWALKS!AD65+SIDEWALKS!AD117 -> 0 | H42: =SIDEWALKS!AD66+SIDEWALKS!AD67 -> 0 | J42: =SIDEWALKS!AD68 -> 0 | K42: =SIDEWALKS!AD69 -> 0 | L42: =SIDEWALKS!AD71 -> 0 | M42: =SIDEWALKS!AD73 -> 0 | N42: =SIDEWALKS!AG88+SIDEWALKS!AG92+SIDEWALKS!AG91+SIDEWALKS!BH28+SIDEWALKS!BG28+SIDEWALKS!BF28 -> 0 | O42: =SIDEWALKS!AG97+SIDEWALKS!AG99+SIDEWALKS!AG100+SIDEWALKS!AG101+SIDEWALKS!Q55 -> 0 | P42: =SIDEWALKS!AD84 -> 0 | Q42: =SIDEWALKS!AD82+SIDEWALKS!AD83 -> 0 | R42: =SIDEWALKS!AD115+SIDEWALKS!AD116 -> 0 | S42: =SIDEWALKS!AD85 -> 0 | T42: =IF(C42=0,0,SUM(G42:S42)/C42) -> 0 | U42: =SUM(G42:S42) -> 0 | V42: =IF(C42=0,0,1-(U42/E42)) -> 0 | W42: =SUM(SIDEWALKS!N38:O40) -> 0 | X42: =SIDEWALKS!W31 -> 0 | Y42: =X42-U42 -> 0
A43: WALLS /FOOTING | C43: ='Site Walls'!I71 -> 0 | D43: FF | E43: ='Site Walls'!E47 -> 0 | F43: ='Site Walls'!C48 -> 0 | G43: ='Site Walls'!AF73+'Site Walls'!AF80+'Site Walls'!AF125 -> 0 | H43: ='Site Walls'!AF74+'Site Walls'!AF75 -> 0 | I43: ='Site Walls'!AF78 -> 0 | J43: ='Site Walls'!AF76 -> 0 | K43: ='Site Walls'!AF77 -> 0 | L43: ='Site Walls'!AF79 -> 0 | M43: ='Site Walls'!AF83 -> 0 | N43: ='Site Walls'!AF96+'Site Walls'!AF99+'Site Walls'!AF100+'Site Walls'!O68 -> 0 | O43: =SUM('Site Walls'!AF103:AF122) -> 0 | P43: ='Site Walls'!AF92 -> 0 | Q43: ='Site Walls'!AF90+'Site Walls'!AF91 -> 0 | R43: ='Site Walls'!AF123+'Site Walls'!AF124 -> 0 | S43: ='Site Walls'!AF93 -> 0 | U43: =SUM(G43:S43) -> 0 | V43: =IF(C43=0,0,1-(U43/E43)) -> 0 | W43: ='Site Walls'!L57+'Site Walls'!L58+'Site Walls'!L59 -> 0 | X43: ='Site Walls'!U47 -> 0 | Y43: =X43-U43 -> 0
A44: FOOTINGS | C44: ='Site Walls'!I70 -> 0 | D44: SF | F44: ='Site Walls'!G48 -> 0 | U44: =SUM(G44:S44) -> 0
A45: Garage Walls | C45: ='Garage Walls'!I71 -> 0 | D45: FF | E45: ='Garage Walls'!E49 -> 0 | F45: ='Garage Walls'!C50 -> 0 | G45: ='Garage Walls'!AF73+'Garage Walls'!AF80+'Garage Walls'!AF125 -> 0 | H45: ='Garage Walls'!AF74+'Garage Walls'!AF75 -> 0 | I45: ='Garage Walls'!AF78 -> 0 | J45: ='Garage Walls'!AF76 -> 0 | K45: ='Garage Walls'!AF77 -> 0 | L45: ='Garage Walls'!AF79 -> 0 | M45: ='Garage Walls'!AF83 -> 0 | N45: ='Garage Walls'!AF96+'Garage Walls'!AF99+'Garage Walls'!AF100+'Garage Walls'!O68 -> 0 | O45: =SUM('Garage Walls'!AF103:AF122) -> 0 | P45: ='Garage Walls'!AF92 -> 0 | Q45: ='Garage Walls'!AF90+'Garage Walls'!AF91 -> 0 | R45: ='Garage Walls'!AF123+'Garage Walls'!AF124 -> 0 | S45: ='Garage Walls'!AF93 -> 0 | U45: =SUM(G45:S45) -> 0 | V45: =IF(C45=0,0,1-(U45/E45)) -> 0 | W45: ='Garage Walls'!L57+'Garage Walls'!L58+'Garage Walls'!L59 -> 0 | X45: ='Garage Walls'!U47 -> 0 | Y45: =X45-U45 -> 0
...

Sheet Pricing
A1: COMPANY | C1: CONTACT | D1: Phone | E1: DATE | F1: 3000 PSI W/ ASH PIERS, SOG | G1: 3500 Psi | H1: 4000 psi | I1: 4500 psi | J1: 5000 psi | K1: 3000 PSI Sidewalk and Hardscape | M1: Whitecap update 5/12/2025
A2: =IF(F2=F3,A3,IF(F2=F4,A4,IF(F2=F5,A5,IF(F2=F6,A6,0)))) -> Martin Marrieta | F2: =MIN(IF(F3>0,F3,1000),IF(F4>0,F4,1000),IF(F5>0,F5,1000),IF(F6>0,F6,1000),IF(F7>0,F7,1000),IF(F8>0,F8,1000)) -> 147 | G2: =MIN(IF(G3>0,G3,1000),IF(G4>0,G4,1000),IF(G5>0,G5,1000),IF(G6>0,G6,1000),IF(G7>0,G7,1000),IF(G8>0,G8,1000)) -> 152 | H2: =MIN(IF(H3>0,H3,1000),IF(H4>0,H4,1000),IF(H5>0,H5,1000),IF(H6>0,H6,1000),IF(H7>0,H7,1000),IF(H8>0,H8,1000)) -> 157 | I2: =MIN(IF(I3>0,I3,1000),IF(I4>0,I4,1000),IF(I5>0,I5,1000),IF(I6>0,I6,1000),IF(I7>0,I7,1000),IF(I8>0,I8,1000)) -> 162 | J2: =MIN(IF(J3>0,J3,1000),IF(J4>0,J4,1000),IF(J5>0,J5,1000),IF(J6>0,J6,1000),IF(J7>0,J7,1000),IF(J8>0,J8,1000)) -> 167 | K2: =MIN(IF(K3>0,K3,1000),IF(K4>0,K4,1000),IF(K5>0,K5,1000),IF(K6>0,K6,1000),IF(K7>0,K7,1000),IF(K8>0,K8,1000)) -> 147 | L2: =MIN(IF(L3>0,L3,1000),IF(L4>0,L4,1000),IF(L5>0,L5,1000),IF(L6>0,L6,1000),IF(L7>0,L7,1000),IF(L8>0,L8,1000)) -> 1000 | M2: LUMBER AND ACCSESS | N2: Unit Cost | O2: Unit | P2: CODE | T2: Low Cost calculator
A3: Martin Marrieta | C3: Justin | F3: 147 | G3: =F3+5 -> 152 | H3: =G3+5 -> 157 | I3: =H3+5 -> 162 | J3: =I3+5 -> 167 | K3: =F3 -> 147 | M3: 2 X 4 X 16' | N3: =9/16 -> 0.5625 | O3: /LNFT | T3: MIX 1 | U3: MIX 2 | V3: MIX 3 | W3: MIX 4 | X3: MIX 5 | Y3: MIX 6
M4: 2 X 6 X 16' | N4: =10.5/16 -> 0.65625 | O4: /LNFT | S4: MONO | T4: ='Mono Slab on Grade Garden Style'!BK105 -> 0 | U4: ='Mono Slab on Grade Garden Style'!BM105 -> 0 | V4: ='Mono Slab on Grade Garden Style'!BQ105 -> 0 | W4: ='Mono Slab on Grade Garden Style'!BR105 -> 0 | X4: ='Mono Slab on Grade Garden Style'!BS105 -> 0 | Y4: ='Mono Slab on Grade Garden Style'!BT105 -> 0
M5: 2 X 8 X 16' | N5: 1 | O5: /LNFT | S5: GRADE | T5: ='Gd Beams'!AN36 -> 0 | U5: ='Gd Beams'!AO36 -> 0 | V5: ='Gd Beams'!AP36 -> 0 | W5: ='Gd Beams'!AQ36 -> 0 | X5: ='Gd Beams'!AR36 -> 0 | Y5: ='Gd Beams'!AS36 -> 0 | AA5: =IF(F5>0,F5) -> FALSE
M6: 2 X 10 X 16' | N6: =20/16 -> 1.25 | O6: /LNFT | S6: SOG | T6: ='SLAB ON DECK'!AL27 -> 0 | U6: ='SLAB ON DECK'!AM27 -> 0 | V6: ='SLAB ON DECK'!AN27 -> 0 | W6: ='SLAB ON DECK'!AO27 -> 0 | X6: ='SLAB ON DECK'!AP27 -> 0 | Y6: ='SLAB ON DECK'!AQ27 -> 0
M7: 3/4 " FORMING PLY | N7: 50 | O7: /SHEET | S7: PAVING | T7: ='Private Paving'!AI27 -> 0 | U7: ='Private Paving'!AJ27 -> 0 | V7: ='Private Paving'!AK27 -> 0 | W7: ='Private Paving'!AL27 -> 0 | X7: ='Private Paving'!AM27 -> 0 | Y7: ='Private Paving'!AN27 -> 0
M8: MASONITE SIDING | N8: 19 | O8: /SHEET | S8: PIERS | T8: =PIERS!AS34 -> 0 | U8: =PIERS!AT34 -> 0 | V8: =PIERS!AU34 -> 0 | W8: =PIERS!AV34 -> 0 | X8: =PIERS!AW34 -> 0 | Y8: =PIERS!AX34 -> 0
A9: COST PER INCH FOR BELLS | E9: 1.5 | M9: 1 X 1 TACT STRIP | N9: 0.15 | O9: /LNFT | S9: SIDE WALKS | T9: =SIDEWALKS!AE27 -> 0 | U9: =SIDEWALKS!AF27 -> 0 | V9: =SIDEWALKS!AG27 -> 0 | W9: =SIDEWALKS!AH27 -> 0 | X9: =SIDEWALKS!AI27 -> 0 | Y9: =SIDEWALKS!AJ27 -> 0
A10: DIA. PIERS IN INCHES | M10: 1 X 4 RED WOOD | N10: 1 | O10: /LNFT | S10: MISC | T10: =IF(T4<T5,T4,T5) -> 0 | U10: =IF(U4<U5,U4,U5) -> 0 | V10: =IF(V4<V5,V4,V5) -> 0 | W10: =IF(W4<W5,W4,W5) -> 0 | X10: =IF(X4<X5,X4,X5) -> 0 | Y10: =IF(Y4<Y5,Y4,Y5) -> 0
A11: 12 | B11: 18 | C11: 24 | D11: 30 | E11: 36 | F11: 42 | G11: 48 | H11: 54 | M11: 1 X 6 RED WOOD | N11: 1.25 | O11: /LNFT
A12: 6 | B12: 9 | C12: 10 | D12: 12 | E12: 15 | F12: 18 | G12: 21 | H12: 36 | M12: 1 X 8 RED WOOD | N12: 0.9 | O12: /LNFT | T12: =IF(T6<T7,T6,T7) -> 0 | U12: =IF(U6<U7,U6,U7) -> 0 | V12: =IF(V6<V7,V6,V7) -> 0 | W12: =IF(W6<W7,W6,W7) -> 0 | X12: =IF(X6<X7,X6,X7) -> 0 | Y12: =IF(Y6<Y7,Y6,Y7) -> 0
A13: CASING | K13: 6 | L13: =K13/16 -> 0.375 | M13: ACCESSORIES | N13: 0.04 | O13: /LB
A14: 10 | B14: 12 | C14: 14 | D14: 16 | E14: 18 | F14: 12 | G14: 15 | H14: 18 | K14: 7.2 | L14: =K14/16 -> 0.45 | M14: 2 x 2 x 30 Stakes | N14: 18 | O14: /BNDLE | Q14: GUAGE | R14: DIA. | T14: =IF(T8<T9,T8,T9) -> 0 | U14: =IF(U8<U9,U8,U9) -> 0 | V14: =IF(V8<V9,V8,V9) -> 0 | W14: =IF(W8<W9,W8,W9) -> 0 | X14: =IF(X8<X9,X8,X9) -> 0 | Y14: =IF(Y8<Y9,Y8,Y9) -> 0
A15: DEDUCT | K15: 9.46 | L15: =K15/16 -> 0.59125 | M15: 16p NAILS DUPLEX | N15: 42 | O15: /BOX | Q15: 7 | R15: 0.1793 | T15: =IF(T10<T12,T10,T12) -> 0 | U15: =IF(U10<U12,U10,U12) -> 0 | V15: =IF(V10<V12,V10,V12) -> 0 | W15: =IF(W10<W12,W10,W12) -> 0 | X15: =IF(X10<X12,X10,X12) -> 0 | Y15: =IF(Y10<Y12,Y10,Y12) -> 0
A16: 0 | C16: 0 | D16: 0 | E16: 0 | K16: 11.34 | L16: =K16/16 -> 0.70875 | M16: 8p DUPLEX | N16: 42 | O16: /BOX | Q16: 8 | R16: 0.1644 | T16: =IF(T11<T13,T11,T13) -> 0 | U16: =IF(U11<U13,U11,U13) -> 0 | V16: =IF(V11<V13,V11,V13) -> 0 | W16: =IF(W11<W13,W11,W13) -> 0 | X16: =IF(X11<X13,X11,X13) -> 0 | Y16: =IF(Y11<Y13,Y11,Y13) -> 0
M17: 6p NAILS | N17: 42 | O17: /BOX | Q17: 9 | R17: 0.1495 | T17: =IF(T12<T14,T12,T14) -> 0 | U17: =IF(U12<U14,U12,U14) -> 0 | V17: =IF(V12<V14,V12,V14) -> 0 | W17: =IF(W12<W14,W12,W14) -> 0 | X17: =IF(X12<X14,X12,X14) -> 0 | Y17: =IF(Y12<Y14,Y12,Y14) -> 0
A18: SAND DELIVERED PER TON | D18: 25 | E18: /YD | K18: 6.6 | L18: =K18/16 -> 0.4125 | M18: KEYWAY | N18: 0.78 | O18: /LNFT
A19: ROCK DELEVERED PER TON | D19: 40 | E19: /YD | K19: 8.75 | L19: =K19/16 -> 0.546875 | M19: CHAMFER | N19: 0.16 | O19: /LNFT | Q19: 10 | R19: 0.1345 | T19: =IF(T15<T17,T15,T17) -> 0 | U19: =IF(U15<U17,U15,U17) -> 0 | V19: =IF(V15<V17,V15,V17) -> 0 | W19: =IF(W15<W17,W15,W17) -> 0 | X19: =IF(X15<X17,X15,X17) -> 0 | Y19: =IF(Y15<Y17,Y15,Y17) -> 0
A20: STEEL | K20: 9.59 | L20: =K20/16 -> 0.599375 | M20: WALL TIES | N20: 45 | O20: 50/BOX
A21: REBAR PIERS | D21: 0.6 | E21: /LB | K21: 11.45 | L21: =K21/16 -> 0.715625 | M21: 1 X 2 X 18" STAKES | N21: 8 | O21: /BNDL
A22: REBAR GRADE BEAM | D22: 0.6 | E22: /LB | F22: =Summary!J56 -> 0 | M22: Structural Accessories
A23: REBAR PAVING | D23: 0.55 | E23: /LB | M23: METAL CHAIRS 2.5" | N23: 45 | O23: /BAG/500
A24: DOWEL SPACING / 3/4" & CAP | D24: 2 | E24: /EACH | M24: LIFT INSERT | N24: 12 | O24: /EACH
A25: WIRE MESH | C25: 10 GAGE | D25: 0.4 | E25: /SQ FT | M25: CAMLOCKS | N25: 0.25 | O25: /EACH
A26: WIRE MESH | C26: 8 GAGE | D26: 0.4 | E26: /SQ FT | M26: TURNBUCKLES | N26: 0.75 | O26: /EACH | R26: =R19*0.5 -> 0.06725 | S26: =R19*0.5 -> 0.06725 | T26: 3.145 | U26: 0.2836 | V26: 240 | W26: 12 | X26: =R26*S26*T26*U26*V26*W26 -> 11.617266
A27: WIRE MESH | C27: 6 GAGE | D27: 0.4 | E27: /SQ FT | M27: PATCH MATERIAL | N27: 15 | O27: /BAG
A28: POST TENSION CABLES | D28: 0.65 | E28: /SQ FT | M28: PIER SLEDS | N28: 1.7 | O28: /EACH | Q28: 6X6 | R28: =R19/2*R19/2*3.145*0.2836*20*6 -> 0.48405276
A29: 1/2" SMOOTH DOWELS & CAP | D29: 1.75 | E29: /EACH | M29: PIER BOOTS | N29: 2.7 | O29: /EACH
A30: EQUIPMENT RENTAL | D30: DAY | M30: SLAB CHAIRS | N30: 27 | O30: /BAG
A31: BACKHOE | D31: 385 | E31: /DAY | M31: POLSTERS | N31: 1.25 | O31: /LNFT
A32: BOXBLADE | D32: 245 | E32: /DAY | M32: BRACE INSERTS | N32: 8
A33: BOBCATS | D33: 350 | E33: /DAY | M33: ANCHOR BOLTS | N33: 25.5 | O33: /BOX
A34: TRENCHER | D34: 300 | E34: /DAY | M34: TIE WIRE | N34: 4 | O34: /ROLL
A35: CHIPPING HAMMER | D35: 50 | E35: /DAY | M35: Site Accessories
A36: COMPRESSOR | D36: 150 | E36: /DAY | M36: 2-1/4 PAVING CHAIRS | N36: 20 | O36: /BAG
A37: TOWER LIGHT w/ GENERATOR | D37: 65 | E37: /DAY | M37: 3-1/4 PAVING CHAIRS | N37: 35 | O37: /BAG
A38: GENERATOR | D38: 32 | E38: /DAY | M38: ANCHOR BOLTS 8"x1/2" (50/BX) | N38: 20 | O38: /BOX
A39: SKY LIFT | D39: 420 | E39: /DAY | M39: SPEED DOWEL INSERT w/ BASE | N39: 1 | O39: /EACH
A40: CRANE AND OPERATOR | D40: 1260 | E40: /DAY | M40: SNAP TIES | N40: 40 | O40: /BOX
...

Sheet CONCRETE BIDS
A1: company
A2: address
A3: city, state zip | D3: =NOW() -> 46139.548
A8: FROM: | B8: =Information!C8 -> Chad McKinney | E8: PHONE:
E9: FAX:
A11: RE: | B11: PLEASE SEND WRITTEN QUOTES FOR THE FOLLOWING JOB.
A14: Message
B15: PROJECT-G.C. | E15: CITY | G15: Location
B16: =Information!C2 -> 0 | E16: =Information!C4 -> 0 | G16: =Information!C3 -> 0 | L16: 3000 PSI / 4.5 SACK SIDE WALKS | M16: 3000 PSI 5 SACK PIERS GRADE BEAMS SOG PAVING | N16: 4000 PSI EL. DECK | O16: 5000 PSI BEAMS AND WALLS | P16: 5500 PSI COLUMNS
B19: =Pricing!F1 -> 3000 PSI W/ ASH PIERS, SOG | E19: =PIERS!AT39+'SLAB ON GRADE'!AJ27+'Mono Slab on Grade Building 1'!BI49+'CIP EL. DECK'!AU41+'Gd Beams'!AO37+'SLAB ON DECK'!AK27+COLUMNS!AO37+'Site Walls'!AI43+SIDEWALKS!AH27+'Private Paving'!AJ28+PANELS!AK120 -> 0 | F19: CY
B21: =Pricing!G1 -> 3500 Psi | E21: =PIERS!AU39+'SLAB ON GRADE'!AK27+'Mono Slab on Grade Building 1'!BJ49+'CIP EL. DECK'!AV41+'Gd Beams'!AP37+'SLAB ON DECK'!AL27+COLUMNS!AP37+'Site Walls'!AJ43+SIDEWALKS!AI27+'Private Paving'!AK28+PANELS!AL120 -> 0 | F21: CY
B23: =Pricing!H1 -> 4000 psi | E23: =PIERS!AV39+'SLAB ON GRADE'!AL27+'Mono Slab on Grade Building 1'!BK49+'CIP EL. DECK'!AW41+'Gd Beams'!AQ37+'SLAB ON DECK'!AM27+COLUMNS!AQ37+'Site Walls'!AK43+SIDEWALKS!AJ27+'Private Paving'!AL28+PANELS!AM120 -> 0 | F23: CY
B25: =Pricing!I1 -> 4500 psi | E25: =PIERS!AW39+'SLAB ON GRADE'!AM27+'Mono Slab on Grade Building 1'!BL49+'CIP EL. DECK'!AX41+'Gd Beams'!AR7+'SLAB ON DECK'!AN27+COLUMNS!AR37+'Site Walls'!AL43+SIDEWALKS!AK27+'Private Paving'!AM28+PANELS!AN120 -> 0 | F25: CY
B27: =Pricing!J1 -> 5000 psi | E27: =PIERS!AX39+'SLAB ON GRADE'!AN27+'Mono Slab on Grade Building 1'!BM49+'CIP EL. DECK'!AY41+'Gd Beams'!AS7+'SLAB ON DECK'!AO27+COLUMNS!AS37+'Site Walls'!AM43+SIDEWALKS!AL27+'Private Paving'!AN28+PANELS!AO120 -> 0 | F27: CY
B29: =Pricing!K1 -> 3000 PSI Sidewalk and Hardscape | E29: =PIERS!AY39+'SLAB ON GRADE'!AO27+'Mono Slab on Grade Building 1'!BN49+'CIP EL. DECK'!AZ41+'Gd Beams'!AT7+'SLAB ON DECK'!AP27+COLUMNS!AT37+'Site Walls'!AN43+SIDEWALKS!AM27+'Private Paving'!AO28+PANELS!AP120 -> 0 | F29: CY
E30: =SUM(E19:E29) -> 0
B31: Please price the above mix designs.
E32: Environmental Fee
E33: fuel charge
B35: If accepted by this date | F35: prices will be good through duration of project.
D36: Date
B40: Signature
B43: Company Name

Sheet Mono Slab on Grade Garden Style
B2: JOB NAME | AA2: DATE: | AC2: 37456
B3: =Summary!C2 -> 0 | I3: DWGS SUPPLIED: | K3: NAME | O3: DATE | S3: Rev. | AA3: Entered by: | AC3: =Information!C8 -> Chad McKinney
B4: =Summary!C3 -> 0 | I4: ARCHITECTUAL: | J4: =Summary!K3 -> 0 | O4: =Summary!O3 -> 0 | S4: =Summary!P3 -> 0
B5: =Summary!C4 -> 0 | I5: STRUCTURAL: | J5: =Summary!K4 -> 0 | O5: =Summary!O4 -> 0 | S5: =Summary!P4 -> 0 | AA5: =Information!H5 -> Approved by Chad:
B6: NUMBER | D6: DATE | I6: CIVIL: | J6: =Summary!K5 -> 0 | O6: =Summary!O5 -> 0 | S6: =Summary!P5 -> 0
B7: 0 | D7: 0 | I7: LANDSCAPE: | J7: =Summary!K6 -> 0 | O7: =Summary!O6 -> 0 | S7: =Summary!P6 -> 0 | AA7: =Information!H6 -> Approved by Edward:
B8: 0 | D8: 0 | G8: Concrete Supplier | J8: =Pricing!A2 -> Martin Marrieta
B9: TYPE | C9: BLD # | D9: SQUARE FOOTAGE | F9: THICK INCH | G9: QTY | H9: CABLE | I9: MIX DESIGN | J9: INCH OF SAND | K9: PERM. EDGE | L9: REINFORCING | N9: WIRE MESH Y/N | O9: EXP GB | Q9: Drops | S9: GRADE BEAMS | AC9: STEEL WT LBS | AD9: TOTAL YDS CON CRETE | AE9: PRICE PER SQ FT | AF9: TOTAL PRICE EACH | AG9: SF Per Yard | AV9: yrds conc. Beams | CB9: =SUM(BZ29:CD29) -> 0 | CO9: drops | CP9: Drop 2 | CQ9: GB1 | CR9: GB2 | CS9: GB3 | CT9: GB4 | CU9: GB5 | CV9: Horizontal | CW9: Total
G10: SLABS | L10: SIZE | M10: SPACE | O10: TYPE | P10: LN FT | Q10: TYPE | R10: LN FT | S10: TYPE | T10: LN FT | U10: TYPE | V10: LN FT | W10: TYPE | X10: LN FT | Y10: TYPE | Z10: LN FT | AA10: TYPE | AB10: LN FT | AO10: Drops | AQ10: CONCRETE GRADE BEAMS | AY10: rebar grade beams | BD10: TOTAL STEEL | BE10: SLAB REBAR | BF10: SQ FTWIRE MESH | BG10: QTY SLABS | BH10: Traf con | BI10: MIX #1 | BJ10: MIX #2 | BK10: MIX #3 | BL10: MIX #4 | BM10: MIX#5 | BN10: MIX #6 | BO10: TOTAL | BP10: SQ FT CABLES | BQ10: TOTAL PERIMITER | BR10: FF DROPS | BT10: TOTAL SQ FT | BU10: SAND | BW10: TOTAL COST EACH | BX10: TOTAL CONCRETE | BY10: TOTAL STEEL | BZ10: In-House Labor | CA10: Sub Labor | CB10: THICK EDGE | CC10: CURBS | CD10: TIE STEEL | CE10: SUPR | CF10: LUMBER | CG10: EQUIP | CH10: CONTRACT | CI10: ACCESS | CJ10: CABLES | CK10: CARTONS | CL10: WIRE MESH | CM10: SAND | CO10: Poly area | CP10: Poly area | CQ10: Poly area | CR10: poly area | CS10: poly area | CT10: poly area | CU10: poly area
O11: 9 | Q11: 10 | S11: 1 | T11: =K11 -> 0 | U11: 2 | W11: 3 | Y11: 4 | AA11: 5 | AC11: =IF(BG11=0,0,SUM(BD11:BE11)/BG11) -> 0 | AD11: =((D11*F11/324)*(1+K$71)+AV11) -> 0 | AE11: =IF(D11=0,0,AF11/D11) -> 0 | AF11: =SUM(BW11)*(1+M$64+Summary!P$64) -> 0 | AG11: =D11/AD11 -> #DIV/0! | AH11: =AF11*G11 -> 0 | AO11: =IF(O11=1,P11*$T$52,0)+IF(O11=2,P11*$T$53,0)+IF(O11=3,P11*$T$54,0)+IF(O11=4,P11*$T$55,0)+IF(O11=5,P11*$T$56,0)+IF(O11=6,P11*$T$57,0)+IF(O11=7,P11*$T$58,0)+IF(O11=8,P11*$T$59,0)+IF(O11=9,P11*$T$60,0)+IF(O11=10,P11*$T$61,0) -> 0 | AP11: =IF(Q11=1,R11*$T$52,0)+IF(Q11=2,R11*$T$53,0)+IF(Q11=3,R11*$T$54,0)+IF(Q11=4,R11*$T$55,0)+IF(Q11=5,R11*$T$56,0)+IF(Q11=6,R11*$T$57,0)+IF(Q11=7,R11*$T$58,0)+IF(Q11=8,R11*$T$59,0)+IF(Q11=9,R11*$T$60,0)+IF(Q11=10,R11*$T$61,0) -> 0 | AQ11: =IF(S11=1,T11*$T$52,0)+IF(S11=2,T11*$T$53,0)+IF(S11=3,T11*$T$54,0)+IF(S11=4,T11*$T$55,0)+IF(S11=5,T11*$T$56,0)+IF(S11=6,T11*$T$57,0)+IF(S11=7,T11*$T$58,0)+IF(S11=8,T11*$T$59,0)+IF(S11=9,T11*$T$60,0)+IF(S11=10,T11*$T$61,0) -> 0 | AR11: =IF(U11=1,V11*$T$52,0)+IF(U11=2,V11*$T$53,0)+IF(U11=3,V11*$T$54,0)+IF(U11=4,V11*$T$55,0)+IF(U11=5,V11*$T$56,0)+IF(U11=6,V11*$T$57,0)+IF(U11=7,V11*$T$58,0)+IF(U11=8,V11*$T$59,0)+IF(U11=9,V11*$T$60,0)+IF(U11=10,V11*$T$61,0) -> 0 | AS11: =IF(W11=1,X11*$T$52,0)+IF(W11=2,X11*$T$53,0)+IF(W11=3,X11*$T$54,0)+IF(W11=4,X11*$T$55,0)+IF(W11=5,X11*$T$56,0)+IF(W11=6,X11*$T$57,0)+IF(W11=7,X11*$T$58,0)+IF(W11=8,X11*$T$59,0)+IF(W11=9,X11*$T$60,0)+IF(W11=10,X11*$T$61,0) -> 0 | AT11: =IF(Y11=1,Z11*$T$52,0)+IF(Y11=2,Z11*$T$53,0)+IF(Y11=3,Z11*$T$54,0)+IF(Y11=4,Z11*$T$55,0)+IF(Y11=5,Z11*$T$56,0)+IF(Y11=6,Z11*$T$57,0)+IF(Y11=7,Z11*$T$58,0)+IF(Y11=8,Z11*$T$59,0)+IF(Y11=9,Z11*$T$60,0)+IF(Y11=10,Z11*$T$61,0) -> 0 | AU11: =IF(AA11=1,AB11*$T$52,0)+IF(AA11=2,AB11*$T$53,0)+IF(AA11=3,AB11*$T$54,0)+IF(AA11=4,AB11*$T$55,0)+IF(AA11=5,AB11*$T$56,0)+IF(AA11=6,AB11*$T$57,0)+IF(AA11=7,AB11*$T$58,0)+IF(AA11=8,AB11*$T$59,0)+IF(AA11=9,AB11*$T$60,0)+IF(AA11=10,AB11*$T$61,0) -> 0 | AV11: =SUM(AO11:AU11) -> 0 | AW11: =ROUNDUP(IF(O11=1,P11*$P$52,0)+IF(O11=2,P11*$P$53,0)+IF(O11=3,P11*$P$54,0)+IF(O11=4,P11*$P$55,0)+IF(O11=5,P11*$P$56,0)+IF(O11=6,P11*$P$57,0)+IF(O11=7,P11*$P$58,0)+IF(O11=8,P11*$P$59,0)+IF(O11=9,P11*$P$60,0)+IF(O11=10,P11*$P$61,0),0)*BG11 -> 0 | AX11: =ROUNDUP(IF(Q11=1,R11*$P$52,0)+IF(Q11=2,R11*$P$53,0)+IF(Q11=3,R11*$P$54,0)+IF(Q11=4,R11*$P$55,0)+IF(Q11=5,R11*$P$56,0)+IF(Q11=6,R11*$P$57,0)+IF(Q11=7,R11*$P$58,0)+IF(Q11=8,R11*$P$59,0)+IF(Q11=9,R11*$P$60,0)+IF(Q11=10,R11*$P$61,0),0) -> 0 | AY11: =ROUNDUP(IF(S11=1,T11*$P$52,0)+IF(S11=2,T11*$P$53,0)+IF(S11=3,T11*$P$54,0)+IF(S11=4,T11*$P$55,0)+IF(S11=5,T11*$P$56,0)+IF(S11=6,T11*$P$57,0)+IF(S11=7,T11*$P$58,0)+IF(S11=8,T11*$P$59,0)+IF(S11=9,T11*$P$60,0)+IF(S11=10,T11*$P$61,0),0) -> 0 | AZ11: =ROUNDUP(IF(U11=1,V11*$P$52,0)+IF(U11=2,V11*$P$53,0)+IF(U11=3,V11*$P$54,0)+IF(U11=4,V11*$P$55,0)+IF(U11=5,V11*$P$56,0)+IF(U11=6,V11*$P$57,0)+IF(U11=7,V11*$P$58,0)+IF(U11=8,V11*$P$59,0)+IF(U11=9,V11*$P$60,0)+IF(U11=10,V11*$P$61,0),0) -> 0 | BA11: =ROUNDUP(IF(W11=1,X11*$P$52,0)+IF(W11=2,X11*$P$53,0)+IF(W11=3,X11*$P$54,0)+IF(W11=4,X11*$P$55,0)+IF(W11=5,X11*$P$56,0)+IF(W11=6,X11*$P$57,0)+IF(W11=7,X11*$P$58,0)+IF(W11=8,X11*$P$59,0)+IF(W11=9,X11*$P$60,0)+IF(W11=10,X11*$P$61,0),0) -> 0 | BB11: =ROUNDUP(IF(Y11=1,Z11*$P$52,0)+IF(Y11=2,Z11*$P$53,0)+IF(Y11=3,Z11*$P$54,0)+IF(Y11=4,Z11*$P$55,0)+IF(Y11=5,Z11*$P$56,0)+IF(Y11=6,Z11*$P$57,0)+IF(Y11=7,Z11*$P$58,0)+IF(Y11=8,Z11*$P$59,0)+IF(Y11=9,Z11*$P$60,0)+IF(Y11=10,Z11*$P$61,0),0) -> 0 | BC11: =ROUNDUP(IF(AA11=1,AB11*$P$52,0)+IF(AA11=2,AB11*$P$53,0)+IF(AA11=3,AB11*$P$54,0)+IF(AA11=4,AB11*$P$55,0)+IF(AA11=5,AB11*$P$56,0)+IF(AA11=6,AB11*$P$57,0)+IF(AA11=7,AB11*$P$58,0)+IF(AA11=8,AB11*$P$59,0)+IF(AA11=9,AB11*$P$60,0)+IF(AA11=10,AB11*$P$61,0),0) -> 0 | BD11: =SUM(AW11:BC11)*BG11 -> 0 | BE11: =IF(M11=0,0,(M11/12+M11/12)/(M11/12*M11/12)*D11*((L11/16*L11/16)*10.6870159))*(1+K$74)*BG11 -> 0 | BF11: =IF(N11="Y",D11*(1+K$75)*BG11,0) -> 0 | BG11: =G11 -> 0 | BH11: =IF(N11="y",D11,0) -> 0 | BI11: =IF($I11=1,$AD11,0)*BG11 -> 0 | BJ11: =IF($I11=2,$AD11,0)*BG11 -> 0 | BK11: =IF($I11=3,$AD11,0)*BG11 -> 0 | BL11: =IF($I11=4,$AD11,0)*BG11 -> 0 | BM11: =IF($I11=5,$AD11,0)*BG11 -> 0 | BN11: =IF($I11=6,$AD11,0)*BG11 -> 0 | BO11: =SUM(BI11:BN11) -> 0 | BP11: =IF(H11="N",0,D11)*BG11 -> 0 | BQ11: =K11*BG11 -> 0 | BR11: =IF(O11=1,D$52*P11/12,IF(O11=2,D$53*P11/12,IF(O11=3,D$54*P11/12,IF(O11=4,D$55*P11/12,IF(O11=5,D$56*P11/12,IF(O11=6,D$57*P11/12,IF(O11=7,D$58*P11/12,IF(O11=8,D$59*P11/12,IF(O11=9,D$60*P11/12,IF(O11=10,D$61*P11/12,0))))))*BG11)))) -> 0 | BS11: =IF(Q11=1,D$52*R11/12,IF(Q11=2,D$53*R11/12,IF(Q11=3,D$54*R11/12,IF(Q11=4,D$55*R11/12,IF(Q11=5,D$56*R11/12,IF(Q11=6,D$57*R11/12,IF(Q11=7,D$58*R11/12,IF(Q11=8,D$59*R11/12,IF(Q11=9,D$60*R11/12,IF(Q11=10,D$61*R11/12,0))))))*BG11)))) -> 0 | BT11: =D11*BG11 -> 0 | BU11: =D11*J11/324*(1+K$77)*BG11 -> 0 | BV11: =AC11*BG11 -> 0 | BW11: =IF(BG11=0,0,SUM(BX11:CM11)/BG11) -> 0 | BX11: =(BI11*Pricing!F$2+BJ11*Pricing!G$2+BK11*Pricing!H$2+BL11*Pricing!I$2+BM11*Pricing!J$2+BN11*Pricing!K$2)*IF(AC$63="N",(1+AE$63),1) -> 0 | BY11: =AC11*G$74*IF(AC$63="n",1+AE$63,1)*BG11 -> 0 | BZ11: =IF(I$83=0,0,D11*(SUM(L$83:M$86)+L$88)/I$83*BG11) -> 0 | CA11: =IF(I$83=0,0,D11*(SUM(O$83:P$86)+O$88)/I$83*BG11) -> 0 | CB11: =BR11+BS11*E$87 -> 0 | CD11: =BD11/2000*E$89 -> 0 | CE11: =IF(D$49=0,0,SUM(O$92:P$96)/D$49*D11)*BG11 -> 0 | CF11: =IF(D$49=0,0,SUM(AF$72:AF$99)/D$49*D11*BG11) -> 0 | CG11: =IF(D$49=0,0,SUM(O$98:P$103)/D$49*D11)*BG11 -> 0 | CH11: =IF(D$49=0,0,SUM(O$105:O$111)/D$49)*D11*BG11 -> 0 | CI11: =IF(D$49=0,0,SUM(AF$100:AF$111)/D$49*D11*BG11) -> 0 | CJ11: =IF(J$76>0,J$76/D$49*D11*G11,BP11*(G$76*(1+AE$63))) -> 0 | CK11: =IF(L$78=0,0,O$78/L$78)*AW11+IF(L$79=0,0,O$79/L$79)*BC11+IF(L$80=0,0,O$80/L$80)*BC11 -> 0 | CL11: =BF11*G$75*IF(AC$63="Y",1,1+AE$63) -> 0 | CM11: =BU11*G$77*IF(AC$63="Y",1,1+AE$63) -> 0 | CO11: =IF(O11=1,P11*$AM$52,0)+IF(O11=2,P11*$AM$53,0)+IF(O11=3,P11*$AM$54,0)+IF(O11=4,P11*$AM$55,0)+IF(O11=5,P11*$AM$56,0)+IF(O11=6,P11*$AM$57,0)+IF(O11=7,P11*$AM$58,0)+IF(O11=8,P11*$AM$59,0)+IF(O11=9,P11*$AM$60,0)+IF(O11=10,P11*$AM$61,0) -> 0 | CP11: =IF(Q11=1,R11*$AM$52,0)+IF(Q11=2,R11*$AM$53,0)+IF(Q11=3,R11*$AM$54,0)+IF(Q11=4,R11*$AM$55,0)+IF(Q11=5,R11*$AM$56,0)+IF(Q11=6,R11*$AM$57,0)+IF(Q11=7,R11*$AM$58,0)+IF(Q11=8,R11*$AM$59,0)+IF(Q11=9,R11*$AM$60,0)+IF(Q11=10,R11*$AM$61,0) -> 0 | CQ11: =IF(S11=1,T11*$AM$52,0)+IF(S11=2,T11*$AM$53,0)+IF(S11=3,T11*$AM$54,0)+IF(S11=4,T11*$AM$55,0)+IF(S11=5,T11*$AM$56,0)+IF(S11=6,T11*$AM$57,0)+IF(S11=7,T11*$AM$58,0)+IF(S11=8,T11*$AM$59,0)+IF(S11=9,T11*$AM$60,0)+IF(S11=10,T11*$AM$61,0) -> 0 | CR11: =IF(U11=1,V11*$AM$52,0)+IF(U11=2,V11*$AM$53,0)+IF(U11=3,V11*$AM$54,0)+IF(U11=4,V11*$AM$55,0)+IF(U11=5,V11*$AM$56,0)+IF(U11=6,V11*$AM$57,0)+IF(U11=7,V11*$AM$58,0)+IF(U11=8,V11*$AM$59,0)+IF(U11=9,V11*$AM$60,0)+IF(U11=10,V11*$AM$61,0) -> 0 | CS11: =IF(W11=1,X11*$AM$52,0)+IF(W11=2,X11*$AM$53,0)+IF(W11=3,X11*$AM$54,0)+IF(W11=4,X11*$AM$55,0)+IF(W11=5,X11*$AM$56,0)+IF(W11=6,X11*$AM$57,0)+IF(W11=7,X11*$AM$58,0)+IF(W11=8,X11*$AM$59,0)+IF(W11=9,X11*$AM$60,0)+IF(W11=10,X11*$AM$61,0) -> 0 | CT11: =IF(Y11=1,Z11*$AM$52,0)+IF(Y11=2,Z11*$AM$53,0)+IF(Y11=3,Z11*$AM$54,0)+IF(Y11=4,Z11*$AM$55,0)+IF(Y11=5,Z11*$AM$56,0)+IF(Y11=6,Z11*$AM$57,0)+IF(Y11=7,Z11*$AM$58,0)+IF(Y11=8,Z11*$AM$59,0)+IF(Y11=9,Z11*$AM$60,0)+IF(Y11=10,Z11*$AM$61,0) -> 0 | CU11: =IF(AA11=1,AB11*$AM$52,0)+IF(AA11=2,AB11*$AM$53,0)+IF(AA11=3,AB11*$AM$54,0)+IF(AA11=4,AB11*$AM$55,0)+IF(AA11=5,AB11*$AM$56,0)+IF(AA11=6,AB11*$AM$57,0)+IF(AA11=7,AB11*$AM$58,0)+IF(AA11=8,AB11*$AM$59,0)+IF(AA11=9,AB11*$AM$60,0)+IF(AA11=10,AB11*$AM$61,0) -> 0 | CV11: =D11 -> 0 | CW11: =SUM(CO11:CV11)*BG11 -> 0
O12: 9 | Q12: 10 | S12: 1 | T12: =K12 -> 0 | U12: 2 | W12: 3 | Y12: 4 | AA12: 5 | AC12: =IF(BG12=0,0,SUM(BD12:BE12)/BG12) -> 0 | AD12: =(D12*F12/324)*(1+K$71)+AV12 -> 0 | AE12: =IF(D12=0,0,AF12/D12) -> 0 | AF12: =SUM(BW12)*(1+M$64+Summary!P$64) -> 0 | AG12: =D12/AD12 -> #DIV/0! | AH12: =AF12*G12 -> 0 | AO12: =IF(O12=1,P12*$T$52,0)+IF(O12=2,P12*$T$53,0)+IF(O12=3,P12*$T$54,0)+IF(O12=4,P12*$T$55,0)+IF(O12=5,P12*$T$56,0)+IF(O12=6,P12*$T$57,0)+IF(O12=7,P12*$T$58,0)+IF(O12=8,P12*$T$59,0)+IF(O12=9,P12*$T$60,0)+IF(O12=10,P12*$T$61,0) -> 0 | AP12: =IF(Q12=1,R12*$T$52,0)+IF(Q12=2,R12*$T$53,0)+IF(Q12=3,R12*$T$54,0)+IF(Q12=4,R12*$T$55,0)+IF(Q12=5,R12*$T$56,0)+IF(Q12=6,R12*$T$57,0)+IF(Q12=7,R12*$T$58,0)+IF(Q12=8,R12*$T$59,0)+IF(Q12=9,R12*$T$60,0)+IF(Q12=10,R12*$T$61,0) -> 0 | AQ12: =IF(S12=1,T12*$T$52,0)+IF(S12=2,T12*$T$53,0)+IF(S12=3,T12*$T$54,0)+IF(S12=4,T12*$T$55,0)+IF(S12=5,T12*$T$56,0)+IF(S12=6,T12*$T$57,0)+IF(S12=7,T12*$T$58,0)+IF(S12=8,T12*$T$59,0)+IF(S12=9,T12*$T$60,0)+IF(S12=10,T12*$T$61,0) -> 0 | AR12: =IF(U12=1,V12*$T$52,0)+IF(U12=2,V12*$T$53,0)+IF(U12=3,V12*$T$54,0)+IF(U12=4,V12*$T$55,0)+IF(U12=5,V12*$T$56,0)+IF(U12=6,V12*$T$57,0)+IF(U12=7,V12*$T$58,0)+IF(U12=8,V12*$T$59,0)+IF(U12=9,V12*$T$60,0)+IF(U12=10,V12*$T$61,0) -> 0 | AS12: =IF(W12=1,X12*$T$52,0)+IF(W12=2,X12*$T$53,0)+IF(W12=3,X12*$T$54,0)+IF(W12=4,X12*$T$55,0)+IF(W12=5,X12*$T$56,0)+IF(W12=6,X12*$T$57,0)+IF(W12=7,X12*$T$58,0)+IF(W12=8,X12*$T$59,0)+IF(W12=9,X12*$T$60,0)+IF(W12=10,X12*$T$61,0) -> 0 | AT12: =IF(Y12=1,Z12*$T$52,0)+IF(Y12=2,Z12*$T$53,0)+IF(Y12=3,Z12*$T$54,0)+IF(Y12=4,Z12*$T$55,0)+IF(Y12=5,Z12*$T$56,0)+IF(Y12=6,Z12*$T$57,0)+IF(Y12=7,Z12*$T$58,0)+IF(Y12=8,Z12*$T$59,0)+IF(Y12=9,Z12*$T$60,0)+IF(Y12=10,Z12*$T$61,0) -> 0 | AU12: =IF(AA12=1,AB12*$T$52,0)+IF(AA12=2,AB12*$T$53,0)+IF(AA12=3,AB12*$T$54,0)+IF(AA12=4,AB12*$T$55,0)+IF(AA12=5,AB12*$T$56,0)+IF(AA12=6,AB12*$T$57,0)+IF(AA12=7,AB12*$T$58,0)+IF(AA12=8,AB12*$T$59,0)+IF(AA12=9,AB12*$T$60,0)+IF(AA12=10,AB12*$T$61,0) -> 0 | AV12: =SUM(AO12:AU12) -> 0 | AW12: =ROUNDUP(IF(O12=1,P12*$P$52,0)+IF(O12=2,P12*$P$53,0)+IF(O12=3,P12*$P$54,0)+IF(O12=4,P12*$P$55,0)+IF(O12=5,P12*$P$56,0)+IF(O12=6,P12*$P$57,0)+IF(O12=7,P12*$P$58,0)+IF(O12=8,P12*$P$59,0)+IF(O12=9,P12*$P$60,0)+IF(O12=10,P12*$P$61,0),0)*BG12 -> 0 | AX12: =ROUNDUP(IF(Q12=1,R12*$P$52,0)+IF(Q12=2,R12*$P$53,0)+IF(Q12=3,R12*$P$54,0)+IF(Q12=4,R12*$P$55,0)+IF(Q12=5,R12*$P$56,0)+IF(Q12=6,R12*$P$57,0)+IF(Q12=7,R12*$P$58,0)+IF(Q12=8,R12*$P$59,0)+IF(Q12=9,R12*$P$60,0)+IF(Q12=10,R12*$P$61,0),0) -> 0 | AY12: =ROUNDUP(IF(S12=1,T12*$P$52,0)+IF(S12=2,T12*$P$53,0)+IF(S12=3,T12*$P$54,0)+IF(S12=4,T12*$P$55,0)+IF(S12=5,T12*$P$56,0)+IF(S12=6,T12*$P$57,0)+IF(S12=7,T12*$P$58,0)+IF(S12=8,T12*$P$59,0)+IF(S12=9,T12*$P$60,0)+IF(S12=10,T12*$P$61,0),0) -> 0 | AZ12: =ROUNDUP(IF(U12=1,V12*$P$52,0)+IF(U12=2,V12*$P$53,0)+IF(U12=3,V12*$P$54,0)+IF(U12=4,V12*$P$55,0)+IF(U12=5,V12*$P$56,0)+IF(U12=6,V12*$P$57,0)+IF(U12=7,V12*$P$58,0)+IF(U12=8,V12*$P$59,0)+IF(U12=9,V12*$P$60,0)+IF(U12=10,V12*$P$61,0),0) -> 0 | BA12: =ROUNDUP(IF(W12=1,X12*$P$52,0)+IF(W12=2,X12*$P$53,0)+IF(W12=3,X12*$P$54,0)+IF(W12=4,X12*$P$55,0)+IF(W12=5,X12*$P$56,0)+IF(W12=6,X12*$P$57,0)+IF(W12=7,X12*$P$58,0)+IF(W12=8,X12*$P$59,0)+IF(W12=9,X12*$P$60,0)+IF(W12=10,X12*$P$61,0),0) -> 0 | BB12: =ROUNDUP(IF(Y12=1,Z12*$P$52,0)+IF(Y12=2,Z12*$P$53,0)+IF(Y12=3,Z12*$P$54,0)+IF(Y12=4,Z12*$P$55,0)+IF(Y12=5,Z12*$P$56,0)+IF(Y12=6,Z12*$P$57,0)+IF(Y12=7,Z12*$P$58,0)+IF(Y12=8,Z12*$P$59,0)+IF(Y12=9,Z12*$P$60,0)+IF(Y12=10,Z12*$P$61,0),0) -> 0 | BC12: =ROUNDUP(IF(AA12=1,AB12*$P$52,0)+IF(AA12=2,AB12*$P$53,0)+IF(AA12=3,AB12*$P$54,0)+IF(AA12=4,AB12*$P$55,0)+IF(AA12=5,AB12*$P$56,0)+IF(AA12=6,AB12*$P$57,0)+IF(AA12=7,AB12*$P$58,0)+IF(AA12=8,AB12*$P$59,0)+IF(AA12=9,AB12*$P$60,0)+IF(AA12=10,AB12*$P$61,0),0) -> 0 | BD12: =SUM(AW12:BC12)*BG12 -> 0 | BE12: =IF(M12=0,0,(M12/12+M12/12)/(M12/12*M12/12)*D12*((L12/16*L12/16)*10.6870159))*(1+K$74)*BG12 -> 0 | BF12: =IF(N12="Y",D12*(1+K$75)*BG12,0) -> 0 | BG12: =G12 -> 0 | BH12: =IF(N12="y",D12,0) -> 0 | BI12: =IF($I12=1,$AD12,0)*BG12 -> 0 | BJ12: =IF($I12=2,$AD12,0)*BG12 -> 0 | BK12: =IF($I12=3,$AD12,0)*BG12 -> 0 | BL12: =IF($I12=4,$AD12,0)*BG12 -> 0 | BM12: =IF($I12=5,$AD12,0)*BG12 -> 0 | BN12: =IF($I12=6,$AD12,0)*BG12 -> 0 | BO12: =SUM(BI12:BN12) -> 0 | BP12: =IF(H12="N",0,D12)*BG12 -> 0 | BQ12: =K12*BG12 -> 0 | BR12: =IF(O12=1,D$52*P12/12,IF(O12=2,D$53*P12/12,IF(O12=3,D$54*P12/12,IF(O12=4,D$55*P12/12,IF(O12=5,D$56*P12/12,IF(O12=6,D$57*P12/12,IF(O12=7,D$58*P12/12,IF(O12=8,D$59*P12/12,IF(O12=9,D$60*P12/12,IF(O12=10,D$61*P12/12,0))))))*BG12)))) -> 0 | BS12: =IF(Q12=1,D$52*R12/12,IF(Q12=2,D$53*R12/12,IF(Q12=3,D$54*R12/12,IF(Q12=4,D$55*R12/12,IF(Q12=5,D$56*R12/12,IF(Q12=6,D$57*R12/12,IF(Q12=7,D$58*R12/12,IF(Q12=8,D$59*R12/12,IF(Q12=9,D$60*R12/12,IF(Q12=10,D$61*R12/12,0))))))*BG12)))) -> 0 | BT12: =D12*BG12 -> 0 | BU12: =D12*J12/324*(1+K$77)*BG12 -> 0 | BV12: =AC12*BG12 -> 0 | BW12: =IF(BG12=0,0,SUM(BX12:CM12)/BG12) -> 0 | BX12: =(BI12*Pricing!F$2+BJ12*Pricing!G$2+BK12*Pricing!H$2+BL12*Pricing!I$2+BM12*Pricing!J$2+BN12*Pricing!K$2)*IF(AC$63="N",(1+AE$63),1) -> 0 | BY12: =AC12*G$74*IF(AC$63="n",1+AE$63,1)*BG12 -> 0 | BZ12: =IF(I$83=0,0,D12*(SUM(L$83:M$86)+L$88)/I$83*BG12) -> 0 | CA12: =IF(I$83=0,0,D12*(SUM(O$83:P$86)+O$88)/I$83*BG12) -> 0 | CB12: =BR12+BS12*E$87 -> 0 | CD12: =BD12/2000*E$89 -> 0 | CE12: =IF(D$49=0,0,SUM(O$92:P$96)/D$49*D12)*BG12 -> 0 | CF12: =IF(D$49=0,0,SUM(AF$72:AF$99)/D$49*D12*BG12) -> 0 | CG12: =IF(D$49=0,0,SUM(O$98:P$103)/D$49*D12)*BG12 -> 0 | CH12: =IF(D$49=0,0,SUM(O$105:O$111)/D$49)*D12*BG12 -> 0 | CI12: =IF(D$49=0,0,SUM(AF$100:AF$111)/D$49*D12*BG12) -> 0 | CJ12: =IF(J$76>0,J$76/D$49*D12*G12,BP12*(G$76*(1+AE$63))) -> 0 | CK12: =IF(L$78=0,0,O$78/L$78)*AW12+IF(L$79=0,0,O$79/L$79)*BC12+IF(L$80=0,0,O$80/L$80)*BC12 -> 0 | CL12: =BF12*G$75*IF(AC$63="Y",1,1+AE$63) -> 0 | CM12: =BU12*G$77*IF(AC$63="Y",1,1+AE$63) -> 0 | CO12: =IF(O12=1,P12*$AM$52,0)+IF(O12=2,P12*$AM$53,0)+IF(O12=3,P12*$AM$54,0)+IF(O12=4,P12*$AM$55,0)+IF(O12=5,P12*$AM$56,0)+IF(O12=6,P12*$AM$57,0)+IF(O12=7,P12*$AM$58,0)+IF(O12=8,P12*$AM$59,0)+IF(O12=9,P12*$AM$60,0)+IF(O12=10,P12*$AM$61,0) -> 0 | CP12: =IF(Q12=1,R12*$AM$52,0)+IF(Q12=2,R12*$AM$53,0)+IF(Q12=3,R12*$AM$54,0)+IF(Q12=4,R12*$AM$55,0)+IF(Q12=5,R12*$AM$56,0)+IF(Q12=6,R12*$AM$57,0)+IF(Q12=7,R12*$AM$58,0)+IF(Q12=8,R12*$AM$59,0)+IF(Q12=9,R12*$AM$60,0)+IF(Q12=10,R12*$AM$61,0) -> 0 | CQ12: =IF(S12=1,T12*$AM$52,0)+IF(S12=2,T12*$AM$53,0)+IF(S12=3,T12*$AM$54,0)+IF(S12=4,T12*$AM$55,0)+IF(S12=5,T12*$AM$56,0)+IF(S12=6,T12*$AM$57,0)+IF(S12=7,T12*$AM$58,0)+IF(S12=8,T12*$AM$59,0)+IF(S12=9,T12*$AM$60,0)+IF(S12=10,T12*$AM$61,0) -> 0 | CR12: =IF(U12=1,V12*$AM$52,0)+IF(U12=2,V12*$AM$53,0)+IF(U12=3,V12*$AM$54,0)+IF(U12=4,V12*$AM$55,0)+IF(U12=5,V12*$AM$56,0)+IF(U12=6,V12*$AM$57,0)+IF(U12=7,V12*$AM$58,0)+IF(U12=8,V12*$AM$59,0)+IF(U12=9,V12*$AM$60,0)+IF(U12=10,V12*$AM$61,0) -> 0 | CS12: =IF(W12=1,X12*$AM$52,0)+IF(W12=2,X12*$AM$53,0)+IF(W12=3,X12*$AM$54,0)+IF(W12=4,X12*$AM$55,0)+IF(W12=5,X12*$AM$56,0)+IF(W12=6,X12*$AM$57,0)+IF(W12=7,X12*$AM$58,0)+IF(W12=8,X12*$AM$59,0)+IF(W12=9,X12*$AM$60,0)+IF(W12=10,X12*$AM$61,0) -> 0 | CT12: =IF(Y12=1,Z12*$AM$52,0)+IF(Y12=2,Z12*$AM$53,0)+IF(Y12=3,Z12*$AM$54,0)+IF(Y12=4,Z12*$AM$55,0)+IF(Y12=5,Z12*$AM$56,0)+IF(Y12=6,Z12*$AM$57,0)+IF(Y12=7,Z12*$AM$58,0)+IF(Y12=8,Z12*$AM$59,0)+IF(Y12=9,Z12*$AM$60,0)+IF(Y12=10,Z12*$AM$61,0) -> 0 | CU12: =IF(AA12=1,AB12*$AM$52,0)+IF(AA12=2,AB12*$AM$53,0)+IF(AA12=3,AB12*$AM$54,0)+IF(AA12=4,AB12*$AM$55,0)+IF(AA12=5,AB12*$AM$56,0)+IF(AA12=6,AB12*$AM$57,0)+IF(AA12=7,AB12*$AM$58,0)+IF(AA12=8,AB12*$AM$59,0)+IF(AA12=9,AB12*$AM$60,0)+IF(AA12=10,AB12*$AM$61,0) -> 0 | CV12: =D12 -> 0 | CW12: =SUM(CO12:CV12)*BG12 -> 0
O13: 9 | Q13: 10 | S13: 1 | T13: =K13 -> 0 | U13: 2 | W13: 3 | Y13: 4 | AA13: 5 | AC13: =IF(BG13=0,0,SUM(BD13:BE13)/BG13) -> 0 | AD13: =(D13*F13/324)*(1+K$71)+AV13 -> 0 | AE13: =IF(D13=0,0,AF13/D13) -> 0 | AF13: =SUM(BW13)*(1+M$64+Summary!P$64) -> 0 | AG13: =D13/AD13 -> #DIV/0! | AH13: =AF13*G13 -> 0 | AO13: =IF(O13=1,P13*$T$52,0)+IF(O13=2,P13*$T$53,0)+IF(O13=3,P13*$T$54,0)+IF(O13=4,P13*$T$55,0)+IF(O13=5,P13*$T$56,0)+IF(O13=6,P13*$T$57,0)+IF(O13=7,P13*$T$58,0)+IF(O13=8,P13*$T$59,0)+IF(O13=9,P13*$T$60,0)+IF(O13=10,P13*$T$61,0) -> 0 | AP13: =IF(Q13=1,R13*$T$52,0)+IF(Q13=2,R13*$T$53,0)+IF(Q13=3,R13*$T$54,0)+IF(Q13=4,R13*$T$55,0)+IF(Q13=5,R13*$T$56,0)+IF(Q13=6,R13*$T$57,0)+IF(Q13=7,R13*$T$58,0)+IF(Q13=8,R13*$T$59,0)+IF(Q13=9,R13*$T$60,0)+IF(Q13=10,R13*$T$61,0) -> 0 | AQ13: =IF(S13=1,T13*$T$52,0)+IF(S13=2,T13*$T$53,0)+IF(S13=3,T13*$T$54,0)+IF(S13=4,T13*$T$55,0)+IF(S13=5,T13*$T$56,0)+IF(S13=6,T13*$T$57,0)+IF(S13=7,T13*$T$58,0)+IF(S13=8,T13*$T$59,0)+IF(S13=9,T13*$T$60,0)+IF(S13=10,T13*$T$61,0) -> 0 | AR13: =IF(U13=1,V13*$T$52,0)+IF(U13=2,V13*$T$53,0)+IF(U13=3,V13*$T$54,0)+IF(U13=4,V13*$T$55,0)+IF(U13=5,V13*$T$56,0)+IF(U13=6,V13*$T$57,0)+IF(U13=7,V13*$T$58,0)+IF(U13=8,V13*$T$59,0)+IF(U13=9,V13*$T$60,0)+IF(U13=10,V13*$T$61,0) -> 0 | AS13: =IF(W13=1,X13*$T$52,0)+IF(W13=2,X13*$T$53,0)+IF(W13=3,X13*$T$54,0)+IF(W13=4,X13*$T$55,0)+IF(W13=5,X13*$T$56,0)+IF(W13=6,X13*$T$57,0)+IF(W13=7,X13*$T$58,0)+IF(W13=8,X13*$T$59,0)+IF(W13=9,X13*$T$60,0)+IF(W13=10,X13*$T$61,0) -> 0 | AT13: =IF(Y13=1,Z13*$T$52,0)+IF(Y13=2,Z13*$T$53,0)+IF(Y13=3,Z13*$T$54,0)+IF(Y13=4,Z13*$T$55,0)+IF(Y13=5,Z13*$T$56,0)+IF(Y13=6,Z13*$T$57,0)+IF(Y13=7,Z13*$T$58,0)+IF(Y13=8,Z13*$T$59,0)+IF(Y13=9,Z13*$T$60,0)+IF(Y13=10,Z13*$T$61,0) -> 0 | AU13: =IF(AA13=1,AB13*$T$52,0)+IF(AA13=2,AB13*$T$53,0)+IF(AA13=3,AB13*$T$54,0)+IF(AA13=4,AB13*$T$55,0)+IF(AA13=5,AB13*$T$56,0)+IF(AA13=6,AB13*$T$57,0)+IF(AA13=7,AB13*$T$58,0)+IF(AA13=8,AB13*$T$59,0)+IF(AA13=9,AB13*$T$60,0)+IF(AA13=10,AB13*$T$61,0) -> 0 | AV13: =SUM(AO13:AU13) -> 0 | AW13: =ROUNDUP(IF(O13=1,P13*$P$52,0)+IF(O13=2,P13*$P$53,0)+IF(O13=3,P13*$P$54,0)+IF(O13=4,P13*$P$55,0)+IF(O13=5,P13*$P$56,0)+IF(O13=6,P13*$P$57,0)+IF(O13=7,P13*$P$58,0)+IF(O13=8,P13*$P$59,0)+IF(O13=9,P13*$P$60,0)+IF(O13=10,P13*$P$61,0),0)*BG13 -> 0 | AX13: =ROUNDUP(IF(Q13=1,R13*$P$52,0)+IF(Q13=2,R13*$P$53,0)+IF(Q13=3,R13*$P$54,0)+IF(Q13=4,R13*$P$55,0)+IF(Q13=5,R13*$P$56,0)+IF(Q13=6,R13*$P$57,0)+IF(Q13=7,R13*$P$58,0)+IF(Q13=8,R13*$P$59,0)+IF(Q13=9,R13*$P$60,0)+IF(Q13=10,R13*$P$61,0),0) -> 0 | AY13: =ROUNDUP(IF(S13=1,T13*$P$52,0)+IF(S13=2,T13*$P$53,0)+IF(S13=3,T13*$P$54,0)+IF(S13=4,T13*$P$55,0)+IF(S13=5,T13*$P$56,0)+IF(S13=6,T13*$P$57,0)+IF(S13=7,T13*$P$58,0)+IF(S13=8,T13*$P$59,0)+IF(S13=9,T13*$P$60,0)+IF(S13=10,T13*$P$61,0),0) -> 0 | AZ13: =ROUNDUP(IF(U13=1,V13*$P$52,0)+IF(U13=2,V13*$P$53,0)+IF(U13=3,V13*$P$54,0)+IF(U13=4,V13*$P$55,0)+IF(U13=5,V13*$P$56,0)+IF(U13=6,V13*$P$57,0)+IF(U13=7,V13*$P$58,0)+IF(U13=8,V13*$P$59,0)+IF(U13=9,V13*$P$60,0)+IF(U13=10,V13*$P$61,0),0) -> 0 | BA13: =ROUNDUP(IF(W13=1,X13*$P$52,0)+IF(W13=2,X13*$P$53,0)+IF(W13=3,X13*$P$54,0)+IF(W13=4,X13*$P$55,0)+IF(W13=5,X13*$P$56,0)+IF(W13=6,X13*$P$57,0)+IF(W13=7,X13*$P$58,0)+IF(W13=8,X13*$P$59,0)+IF(W13=9,X13*$P$60,0)+IF(W13=10,X13*$P$61,0),0) -> 0 | BB13: =ROUNDUP(IF(Y13=1,Z13*$P$52,0)+IF(Y13=2,Z13*$P$53,0)+IF(Y13=3,Z13*$P$54,0)+IF(Y13=4,Z13*$P$55,0)+IF(Y13=5,Z13*$P$56,0)+IF(Y13=6,Z13*$P$57,0)+IF(Y13=7,Z13*$P$58,0)+IF(Y13=8,Z13*$P$59,0)+IF(Y13=9,Z13*$P$60,0)+IF(Y13=10,Z13*$P$61,0),0) -> 0 | BC13: =ROUNDUP(IF(AA13=1,AB13*$P$52,0)+IF(AA13=2,AB13*$P$53,0)+IF(AA13=3,AB13*$P$54,0)+IF(AA13=4,AB13*$P$55,0)+IF(AA13=5,AB13*$P$56,0)+IF(AA13=6,AB13*$P$57,0)+IF(AA13=7,AB13*$P$58,0)+IF(AA13=8,AB13*$P$59,0)+IF(AA13=9,AB13*$P$60,0)+IF(AA13=10,AB13*$P$61,0),0) -> 0 | BD13: =SUM(AW13:BC13)*BG13 -> 0 | BE13: =IF(M13=0,0,(M13/12+M13/12)/(M13/12*M13/12)*D13*((L13/16*L13/16)*10.6870159))*(1+K$74)*BG13 -> 0 | BF13: =IF(N13="Y",D13*(1+K$75)*BG13,0) -> 0 | BG13: =G13 -> 0 | BH13: =IF(N13="y",D13,0) -> 0 | BI13: =IF($I13=1,$AD13,0)*BG13 -> 0 | BJ13: =IF($I13=2,$AD13,0)*BG13 -> 0 | BK13: =IF($I13=3,$AD13,0)*BG13 -> 0 | BL13: =IF($I13=4,$AD13,0)*BG13 -> 0 | BM13: =IF($I13=5,$AD13,0)*BG13 -> 0 | BN13: =IF($I13=6,$AD13,0)*BG13 -> 0 | BO13: =SUM(BI13:BN13) -> 0 | BP13: =IF(H13="N",0,D13)*BG13 -> 0 | BQ13: =K13*BG13 -> 0 | BR13: =IF(O13=1,D$52*P13/12,IF(O13=2,D$53*P13/12,IF(O13=3,D$54*P13/12,IF(O13=4,D$55*P13/12,IF(O13=5,D$56*P13/12,IF(O13=6,D$57*P13/12,IF(O13=7,D$58*P13/12,IF(O13=8,D$59*P13/12,IF(O13=9,D$60*P13/12,IF(O13=10,D$61*P13/12,0))))))*BG13)))) -> 0 | BS13: =IF(Q13=1,D$52*R13/12,IF(Q13=2,D$53*R13/12,IF(Q13=3,D$54*R13/12,IF(Q13=4,D$55*R13/12,IF(Q13=5,D$56*R13/12,IF(Q13=6,D$57*R13/12,IF(Q13=7,D$58*R13/12,IF(Q13=8,D$59*R13/12,IF(Q13=9,D$60*R13/12,IF(Q13=10,D$61*R13/12,0))))))*BG13)))) -> 0 | BT13: =D13*BG13 -> 0 | BU13: =D13*J13/324*(1+K$77)*BG13 -> 0 | BV13: =AC13*BG13 -> 0 | BW13: =IF(BG13=0,0,SUM(BX13:CM13)/BG13) -> 0 | BX13: =(BI13*Pricing!F$2+BJ13*Pricing!G$2+BK13*Pricing!H$2+BL13*Pricing!I$2+BM13*Pricing!J$2+BN13*Pricing!K$2)*IF(AC$63="N",(1+AE$63),1) -> 0 | BY13: =AC13*G$74*IF(AC$63="n",1+AE$63,1)*BG13 -> 0 | BZ13: =IF(I$83=0,0,D13*(SUM(L$83:M$86)+L$88)/I$83*BG13) -> 0 | CA13: =IF(I$83=0,0,D13*(SUM(O$83:P$86)+O$88)/I$83*BG13) -> 0 | CB13: =BR13+BS13*E$87 -> 0 | CD13: =BD13/2000*E$89 -> 0 | CE13: =IF(D$49=0,0,SUM(O$92:P$96)/D$49*D13)*BG13 -> 0 | CF13: =IF(D$49=0,0,SUM(AF$72:AF$99)/D$49*D13*BG13) -> 0 | CG13: =IF(D$49=0,0,SUM(O$98:P$103)/D$49*D13)*BG13 -> 0 | CH13: =IF(D$49=0,0,SUM(O$105:O$111)/D$49)*D13*BG13 -> 0 | CI13: =IF(D$49=0,0,SUM(AF$100:AF$111)/D$49*D13*BG13) -> 0 | CJ13: =IF(J$76>0,J$76/D$49*D13*G13,BP13*(G$76*(1+AE$63))) -> 0 | CK13: =IF(L$78=0,0,O$78/L$78)*AW13+IF(L$79=0,0,O$79/L$79)*BC13+IF(L$80=0,0,O$80/L$80)*BC13 -> 0 | CL13: =BF13*G$75*IF(AC$63="Y",1,1+AE$63) -> 0 | CM13: =BU13*G$77*IF(AC$63="Y",1,1+AE$63) -> 0 | CO13: =IF(O13=1,P13*$AM$52,0)+IF(O13=2,P13*$AM$53,0)+IF(O13=3,P13*$AM$54,0)+IF(O13=4,P13*$AM$55,0)+IF(O13=5,P13*$AM$56,0)+IF(O13=6,P13*$AM$57,0)+IF(O13=7,P13*$AM$58,0)+IF(O13=8,P13*$AM$59,0)+IF(O13=9,P13*$AM$60,0)+IF(O13=10,P13*$AM$61,0) -> 0 | CP13: =IF(Q13=1,R13*$AM$52,0)+IF(Q13=2,R13*$AM$53,0)+IF(Q13=3,R13*$AM$54,0)+IF(Q13=4,R13*$AM$55,0)+IF(Q13=5,R13*$AM$56,0)+IF(Q13=6,R13*$AM$57,0)+IF(Q13=7,R13*$AM$58,0)+IF(Q13=8,R13*$AM$59,0)+IF(Q13=9,R13*$AM$60,0)+IF(Q13=10,R13*$AM$61,0) -> 0 | CQ13: =IF(S13=1,T13*$AM$52,0)+IF(S13=2,T13*$AM$53,0)+IF(S13=3,T13*$AM$54,0)+IF(S13=4,T13*$AM$55,0)+IF(S13=5,T13*$AM$56,0)+IF(S13=6,T13*$AM$57,0)+IF(S13=7,T13*$AM$58,0)+IF(S13=8,T13*$AM$59,0)+IF(S13=9,T13*$AM$60,0)+IF(S13=10,T13*$AM$61,0) -> 0 | CR13: =IF(U13=1,V13*$AM$52,0)+IF(U13=2,V13*$AM$53,0)+IF(U13=3,V13*$AM$54,0)+IF(U13=4,V13*$AM$55,0)+IF(U13=5,V13*$AM$56,0)+IF(U13=6,V13*$AM$57,0)+IF(U13=7,V13*$AM$58,0)+IF(U13=8,V13*$AM$59,0)+IF(U13=9,V13*$AM$60,0)+IF(U13=10,V13*$AM$61,0) -> 0 | CS13: =IF(W13=1,X13*$AM$52,0)+IF(W13=2,X13*$AM$53,0)+IF(W13=3,X13*$AM$54,0)+IF(W13=4,X13*$AM$55,0)+IF(W13=5,X13*$AM$56,0)+IF(W13=6,X13*$AM$57,0)+IF(W13=7,X13*$AM$58,0)+IF(W13=8,X13*$AM$59,0)+IF(W13=9,X13*$AM$60,0)+IF(W13=10,X13*$AM$61,0) -> 0 | CT13: =IF(Y13=1,Z13*$AM$52,0)+IF(Y13=2,Z13*$AM$53,0)+IF(Y13=3,Z13*$AM$54,0)+IF(Y13=4,Z13*$AM$55,0)+IF(Y13=5,Z13*$AM$56,0)+IF(Y13=6,Z13*$AM$57,0)+IF(Y13=7,Z13*$AM$58,0)+IF(Y13=8,Z13*$AM$59,0)+IF(Y13=9,Z13*$AM$60,0)+IF(Y13=10,Z13*$AM$61,0) -> 0 | CU13: =IF(AA13=1,AB13*$AM$52,0)+IF(AA13=2,AB13*$AM$53,0)+IF(AA13=3,AB13*$AM$54,0)+IF(AA13=4,AB13*$AM$55,0)+IF(AA13=5,AB13*$AM$56,0)+IF(AA13=6,AB13*$AM$57,0)+IF(AA13=7,AB13*$AM$58,0)+IF(AA13=8,AB13*$AM$59,0)+IF(AA13=9,AB13*$AM$60,0)+IF(AA13=10,AB13*$AM$61,0) -> 0 | CV13: =D13 -> 0 | CW13: =SUM(CO13:CV13)*BG13 -> 0
